Workbook

Sheet Sheet1
H4: DAFTAR SUPLIER YANG SUDAH DIKIRIMI PROPOSAL EXTRAVAGANZA | AG4: DAFTAR SUPLIER YANG TIDAK DIKIRIMI PROPOSAL EXTRAVAGANZA
H5: No. | I5: NAMA SUPLIER | J5: SURAT | L5: PENERIMA | N5: TANGGAL | P5: HASIL | R5: PENCAIRAN DANA EXTRAVAGANZA | AG5: No. | AH5: NAMA SUPLIER
J6: NOMER | K6: TANGGAL | L6: PIC | M6: WA/EMAIL | N6: TERKIRIM | O6: KONFIRMASI PENERIMAAN | R6: JAN | S6: FEB | T6: MAR | U6: APR | V6: MEI | W6: JUN | X6: JUL | Y6: AGT | Z6: SEPT | AA6: OKT | AB6: NOP | AC6: DES | AD6: YTD TOTAL
A7: =IF(B7="A",A6+1,0) -> 1 | B7: =IF(G7="HIJAU","A",0) -> A | C7: =IF(D7="B",C6+1,0) -> 0 | D7: =IF(G7="MERAH","B",0) -> 0 | E7: =IF(F7="C",E6+1,0) -> 0 | F7: =IF(G7=0,"C",0) -> 0 | G7: HIJAU | H7: 1 | I7: AGRO GUNA MAKMUR, PT | J7: 011/KIU/EXT/2026 | K7: 46044 | L7: Tri | M7: WA | N7: 46044 | O7: 46044 | P7: 0.5% U/ Alfatox dan Kaliandra, 1% u/ RG | Q7: sales 2026 | R7: 674127 | S7: 0 | T7: 385699 | U7: 3387075 | V7: 2485592.5 | AD7: =SUM(R7:AC7) -> 6932493.5 | AG7: 1 | AH7: ARTHA BUANA MANDIRI/GRAHA NIAGA MANDIRI, CV
A8: =IF(B8="A",A7+1,0) -> 2 | B8: =IF(G8="HIJAU","A",0) -> A | C8: =IF(D8="B",C7+1,0) -> 0 | D8: =IF(G8="MERAH","B",0) -> 0 | E8: =IF(F8="C",E7+1,0) -> 0 | F8: =IF(G8=0,"C",0) -> 0 | G8: HIJAU | H8: 2 | I8: AGRO NATURAL TECHNOLOGY, PT | J8: 012/KIU/EXT/2026 | K8: 46042 | L8: Rina | M8: WA | N8: 46049 | O8: 46049 | Q8: Transfer | S8: 10000000 | AD8: =SUM(R8:AC8) -> 10000000 | AG8: 2 | AH8: CHAMPION AGROCHEMICALS INDONESIA, PT
A9: =IF(B9="A",A8+1,0) -> 3 | B9: =IF(G9="HIJAU","A",0) -> A | C9: =IF(D9="B",C8+1,0) -> 0 | D9: =IF(G9="MERAH","B",0) -> 0 | E9: =IF(F9="C",E8+1,0) -> 0 | F9: =IF(G9=0,"C",0) -> 0 | G9: HIJAU | H9: 3 | I9: BASF DISTRIBUTION INDONESIA, PT | J9: 042/KIU/EXT/2026 | K9: 46050 | L9: Badri | M9: WA | N9: 46051 | O9: 46051 | P9: dari PO 02 & 03 | Q9: 30 Jt dari | AD9: =SUM(R9:AC9) -> 0 | AG9: 4 | AH9: MULTIDAYA PUTRA SEJAHTERA, PT
A10: =IF(B10="A",A9+1,0) -> 4 | B10: =IF(G10="HIJAU","A",0) -> A | C10: =IF(D10="B",C9+1,0) -> 0 | D10: =IF(G10="MERAH","B",0) -> 0 | E10: =IF(F10="C",E9+1,0) -> 0 | F10: =IF(G10=0,"C",0) -> 0 | G10: HIJAU | H10: 4 | I10: BENIH CITRA ASIA, PT | J10: 043/KIU/EXT/2026 | K10: 46050 | L10: Fahri | M10: WA | N10: 46051 | O10: 46051 | V10: 251941452 | AD10: =SUM(R10:AC10) -> 251941452 | AG10: 5 | AH10: NUSA PALAPA GEMILANG, PT.
A11: =IF(B11="A",A10+1,0) -> 5 | B11: =IF(G11="HIJAU","A",0) -> A | C11: =IF(D11="B",C10+1,0) -> 0 | D11: =IF(G11="MERAH","B",0) -> 0 | E11: =IF(F11="C",E10+1,0) -> 0 | F11: =IF(G11=0,"C",0) -> 0 | G11: HIJAU | H11: 5 | I11: JAVA KARLOS INDONESIA, PT | J11: 021/KIU/EXT/2026 | K11: 46044 | L11: Daltry | M11: WA | N11: 46044 | O11: 46044 | P11: 2% omset 2025 | U11: 125390172 | AD11: =SUM(R11:AC11) -> 125390172 | AG11: 6 | AH11: PERSADA AGRO SUKSES, PT
A12: =IF(B12="A",A11+1,0) -> 6 | B12: =IF(G12="HIJAU","A",0) -> A | C12: =IF(D12="B",C11+1,0) -> 0 | D12: =IF(G12="MERAH","B",0) -> 0 | E12: =IF(F12="C",E11+1,0) -> 0 | F12: =IF(G12=0,"C",0) -> 0 | G12: HIJAU | H12: 6 | I12: MITRA KREASI DHARMA, PT | J12: 005/KIU/EXT/2026 | K12: 46037 | L12: Sularmanto | M12: WA | N12: 46037 | O12: 46037 | P12: 0.015 | Q12: OMSET SMT 1 - 2026 | AD12: =SUM(R12:AC12) -> 0 | AG12: 7 | AH12: PETANI PANEN MAKMUR, PT
A13: =IF(B13="A",A12+1,0) -> 7 | B13: =IF(G13="HIJAU","A",0) -> A | C13: =IF(D13="B",C12+1,0) -> 0 | D13: =IF(G13="MERAH","B",0) -> 0 | E13: =IF(F13="C",E12+1,0) -> 0 | F13: =IF(G13=0,"C",0) -> 0 | G13: HIJAU | H13: 7 | I13: MITRA TANI ABADI JAYA, CV | J13: 026/KIU/EXT/2026 | K13: 46044 | L13: Suwarno | M13: WA | N13: 46044 | O13: 46044 | P13: 0.01 | Q13: pembayaran 2026 | R13: 12589924 | AD13: =SUM(R13:AC13) -> 12589924 | AG13: 8 | AH13: PUPUK KARYA POLOWIJO, PT
A14: =IF(B14="A",A13+1,0) -> 8 | B14: =IF(G14="HIJAU","A",0) -> A | C14: =IF(D14="B",C13+1,0) -> 0 | D14: =IF(G14="MERAH","B",0) -> 0 | E14: =IF(F14="C",E13+1,0) -> 0 | F14: =IF(G14=0,"C",0) -> 0 | G14: HIJAU | H14: 8 | I14: NUFARM INDONESIA, PT | J14: 006/KIU/EXT/2026 | K14: 46037 | L14: Agus Iwan | M14: WA | N14: 46037 | O14: 46037 | P14: 1% DP Khusus | Q14: non Round up | R14: 9942500 | S14: 6220000 | AD14: =SUM(R14:AC14) -> 16162500 | AG14: 9 | AH14: SAKASAKI INDONESIA, CV
A15: =IF(B15="A",A14+1,0) -> 9 | B15: =IF(G15="HIJAU","A",0) -> A | C15: =IF(D15="B",C14+1,0) -> 0 | D15: =IF(G15="MERAH","B",0) -> 0 | E15: =IF(F15="C",E14+1,0) -> 0 | F15: =IF(G15=0,"C",0) -> 0 | G15: HIJAU | H15: 9 | I15: SINAR GENERAL INDUSTRIES, PT | J15: 027/KIU/EXT/2026 | K15: 46044 | L15: Evi | M15: email | N15: 46044 | O15: 46044 | P15: 0.01 | Q15: omset produk tertentu | S15: 46935504 | AD15: =SUM(R15:AC15) -> 46935504 | AG15: 10 | AH15: STELLAR AGRI INDONESIA, PT
A16: =IF(B16="A",A15+1,0) -> 10 | B16: =IF(G16="HIJAU","A",0) -> A | C16: =IF(D16="B",C15+1,0) -> 0 | D16: =IF(G16="MERAH","B",0) -> 0 | E16: =IF(F16="C",E15+1,0) -> 0 | F16: =IF(G16=0,"C",0) -> 0 | G16: HIJAU | H16: 11 | I16: SONGGOLANGIT PERSADA - DENPASAR | J16: 040/KIU/EXT/2026 | K16: 46049 | L16: Irkham | M16: WA | N16: 46049 | O16: 46049 | P16: 0.01 | Q16: omset sd sebelum acara | AD16: =SUM(R16:AC16) -> 0 | AG16: 11 | AH16: SUMANS MANDIRI SEJAHTERA, PT
A17: =IF(B17="A",A16+1,0) -> 11 | B17: =IF(G17="HIJAU","A",0) -> A | C17: =IF(D17="B",C16+1,0) -> 0 | D17: =IF(G17="MERAH","B",0) -> 0 | E17: =IF(F17="C",E16+1,0) -> 0 | F17: =IF(G17=0,"C",0) -> 0 | G17: HIJAU | H17: 12 | I17: TANI ABADI, CV | J17: 051/KIU/EXT/2026 | K17: 46050 | L17: Lithus | M17: WA | N17: 46051 | O17: 46051 | P17: 0.01 | Q17: target Rp. 2.478.241.714 | AD17: =SUM(R17:AC17) -> 0
A18: =IF(B18="A",A17+1,0) -> 12 | B18: =IF(G18="HIJAU","A",0) -> A | C18: =IF(D18="B",C17+1,0) -> 0 | D18: =IF(G18="MERAH","B",0) -> 0 | E18: =IF(F18="C",E17+1,0) -> 0 | F18: =IF(G18=0,"C",0) -> 0 | G18: HIJAU | H18: 13 | I18: ASIANA CHEMICALINDO LESTARI, PT | J18: 004/KIU/EXT/2026 | K18: 46037 | L18: Putu | M18: WA | N18: 46037 | O18: 46037 | P18: 0.01 | Q18: dari pembayaran | T18: =3333300+1023416 -> 4356716 | V18: 1567571 | AD18: =SUM(R18:AC18) -> 5924287 | AG18: 12 | AH18: SURYA BERKAH PLASTINDO, PT
A19: =IF(B19="A",A18+1,0) -> 13 | B19: =IF(G19="HIJAU","A",0) -> A | C19: =IF(D19="B",C18+1,0) -> 0 | D19: =IF(G19="MERAH","B",0) -> 0 | E19: =IF(F19="C",E18+1,0) -> 0 | F19: =IF(G19=0,"C",0) -> 0 | G19: HIJAU | H19: 14 | I19: BAHTERA BONIAGA LESTARI, PT | J19: 015/KIU/EXT/2026 | K19: 46044 | L19: Iqbal | M19: WA | N19: 46044 | O19: 46044 | Q19: Mutual, Bump, Bahsan | AD19: =SUM(R19:AC19) -> 0 | AG19: 14 | AH19: TANGGUH AGRO NUSA INDONESIA, PT
A20: =IF(B20="A",A19+1,0) -> 14 | B20: =IF(G20="HIJAU","A",0) -> A | C20: =IF(D20="B",C19+1,0) -> 0 | D20: =IF(G20="MERAH","B",0) -> 0 | E20: =IF(F20="C",E19+1,0) -> 0 | F20: =IF(G20=0,"C",0) -> 0 | G20: HIJAU | H20: 15 | I20: BEHN MEYER AGRICARE, PT | J20: 016/KIU/EXT/2026 | K20: 46081 | L20: Alfi | M20: email | N20: 46081 | O20: 46081 | AD20: =SUM(R20:AC20) -> 0 | AG20: 15 | AH20: UTOMO UTOMO, PT
A21: =IF(B21="A",A20+1,0) -> 15 | B21: =IF(G21="HIJAU","A",0) -> A | C21: =IF(D21="B",C20+1,0) -> 0 | D21: =IF(G21="MERAH","B",0) -> 0 | E21: =IF(F21="C",E20+1,0) -> 0 | F21: =IF(G21=0,"C",0) -> 0 | G21: HIJAU | H21: 16 | I21: EXCEL MEG INDO, PT | J21: 018/KIU/EXT/2026 | K21: 46044 | L21: Agung | M21: WA | N21: 46044 | O21: 46044 | AD21: =SUM(R21:AC21) -> 0 | AG21: 17 | AH21: WELL INDONESIA DUTA AGRICULTURE, PT
A22: =IF(B22="A",A21+1,0) -> 16 | B22: =IF(G22="HIJAU","A",0) -> A | C22: =IF(D22="B",C21+1,0) -> 0 | D22: =IF(G22="MERAH","B",0) -> 0 | E22: =IF(F22="C",E21+1,0) -> 0 | F22: =IF(G22=0,"C",0) -> 0 | G22: HIJAU | H22: 17 | I22: GLOBAL AGROTECH, PT | J22: 019/KIU/EXT/2026 | K22: 46044 | L22: Cahyo | M22: WA | N22: 46044 | O22: 46044 | AD22: =SUM(R22:AC22) -> 0 | AG22: 18 | AH22: WINON INTERNATIONAL, PT
A23: =IF(B23="A",A22+1,0) -> 17 | B23: =IF(G23="HIJAU","A",0) -> A | C23: =IF(D23="B",C22+1,0) -> 0 | D23: =IF(G23="MERAH","B",0) -> 0 | E23: =IF(F23="C",E22+1,0) -> 0 | F23: =IF(G23=0,"C",0) -> 0 | G23: HIJAU | H23: 18 | I23: KALATHAM, PT | J23: 023/KIU/EXT/2026 | K23: 46044 | L23: Amin | M23: WA | N23: 46044 | O23: 46044 | AD23: =SUM(R23:AC23) -> 0 | AG23: 19 | AH23: ZINON AGRO INDONESIA, PT
A24: =IF(B24="A",A23+1,0) -> 18 | B24: =IF(G24="HIJAU","A",0) -> A | C24: =IF(D24="B",C23+1,0) -> 0 | D24: =IF(G24="MERAH","B",0) -> 0 | E24: =IF(F24="C",E23+1,0) -> 0 | F24: =IF(G24=0,"C",0) -> 0 | G24: HIJAU | H24: 19 | I24: KARUNIA SUKSES UTAMA, PT | J24: 024/KIU/EXT/2026 | K24: 46044 | L24: Rudy | M24: WA | N24: 46044 | O24: 46044 | AD24: =SUM(R24:AC24) -> 0
A25: =IF(B25="A",A24+1,0) -> 19 | B25: =IF(G25="HIJAU","A",0) -> A | C25: =IF(D25="B",C24+1,0) -> 0 | D25: =IF(G25="MERAH","B",0) -> 0 | E25: =IF(F25="C",E24+1,0) -> 0 | F25: =IF(G25=0,"C",0) -> 0 | G25: HIJAU | H25: 20 | I25: AGRI MAKMUR PERTIWI, PT | J25: 031/KIU/EXT/2026 | K25: 46049 | L25: Erwin | M25: WA | N25: 46049 | O25: 46049 | AD25: =SUM(R25:AC25) -> 0
A26: =IF(B26="A",A25+1,0) -> 20 | B26: =IF(G26="HIJAU","A",0) -> A | C26: =IF(D26="B",C25+1,0) -> 0 | D26: =IF(G26="MERAH","B",0) -> 0 | E26: =IF(F26="C",E25+1,0) -> 0 | F26: =IF(G26=0,"C",0) -> 0 | G26: HIJAU | H26: 21 | I26: ADVANSIA INDOTANI, PT | J26: 002/KIU/EXT/2026 | K26: 46037 | L26: Sholeh | M26: WA | N26: 46037 | O26: 46042 | P26: 0.005 | Q26: Agil, Agus, Amolin | AD26: =SUM(R26:AC26) -> 0
A27: =IF(B27="A",A26+1,0) -> 21 | B27: =IF(G27="HIJAU","A",0) -> A | C27: =IF(D27="B",C26+1,0) -> 0 | D27: =IF(G27="MERAH","B",0) -> 0 | E27: =IF(F27="C",E26+1,0) -> 0 | F27: =IF(G27=0,"C",0) -> 0 | G27: HIJAU | H27: 22 | I27: AGROIRIS CROP PROTECTION INDONESIA, PT | J27: 013/KIU/EXT/2026 | K27: 46044 | L27: Wahyu | M27: WA | N27: 46044 | O27: 46044 | AD27: =SUM(R27:AC27) -> 0
A28: =IF(B28="A",A27+1,0) -> 22 | B28: =IF(G28="HIJAU","A",0) -> A | C28: =IF(D28="B",C27+1,0) -> 0 | D28: =IF(G28="MERAH","B",0) -> 0 | E28: =IF(F28="C",E27+1,0) -> 0 | F28: =IF(G28=0,"C",0) -> 0 | G28: HIJAU | H28: 23 | I28: PETROSIDA GRESIK, PT | J28: 007/KIU/EXT/2026 | K28: 46037 | L28: Anas | M28: WA | N28: 46037 | O28: 46037 | Q28: 50 jt target tercapai 100% | AD28: =SUM(R28:AC28) -> 0
A29: =IF(B29="A",A28+1,0) -> 23 | B29: =IF(G29="HIJAU","A",0) -> A | C29: =IF(D29="B",C28+1,0) -> 0 | D29: =IF(G29="MERAH","B",0) -> 0 | E29: =IF(F29="C",#REF!+1,0) -> 0 | F29: =IF(G29=0,"C",0) -> 0 | G29: HIJAU | H29: 40 | I29: SARI KRESNA KIMIA, PT | J29: 009/KIU/EXT/2026 | K29: 46037 | L29: Rudiyanto | M29: WA | N29: 46037 | O29: 46037 | AD29: =SUM(R29:AC29) -> 0
A30: =IF(B30="A",A29+1,0) -> 24 | B30: =IF(G30="HIJAU","A",0) -> A | C30: =IF(D30="B",C29+1,0) -> 0 | D30: =IF(G30="MERAH","B",0) -> 0 | E30: =IF(F30="C",E29+1,0) -> 0 | F30: =IF(G30=0,"C",0) -> 0 | G30: HIJAU | H30: 30 | I30: MAJU MAKMUR UTOMO, PT | J30: 025/KIU/EXT/2026 | K30: 46044 | L30: Huda | M30: WA | N30: 46044 | O30: 46044 | Q30: produk Bamex | AD30: =SUM(R30:AC30) -> 0
A31: =IF(B31="A",A30+1,0) -> 25 | B31: =IF(G31="HIJAU","A",0) -> A | C31: =IF(D31="B",C30+1,0) -> 0 | D31: =IF(G31="MERAH","B",0) -> 0 | E31: =IF(F31="C",E30+1,0) -> 0 | F31: =IF(G31=0,"C",0) -> 0 | G31: HIJAU | H31: 45 | I31: SONGGOLANGIT PERSADA - SURABAYA | J31: 041/KIU/EXT/2026 | K31: 46049 | L31: Alim | M31: WA | N31: 46049 | O31: 46049 | P31: 0.01 | Q31: omset sd sebelum acara | AD31: =SUM(R31:AC31) -> 0
A32: =IF(B32="A",A31+1,0) -> 26 | B32: =IF(G32="HIJAU","A",0) -> A | C32: =IF(D32="B",C31+1,0) -> 0 | D32: =IF(G32="MERAH","B",0) -> 0 | E32: =IF(F32="C",E30+1,0) -> 0 | F32: =IF(G32=0,"C",0) -> 0 | G32: HIJAU | H32: 4 | I32: AGRICULTURE CONSTRACTION INDONESIA, PT | J32: 032/KIU/EXT/2026 | K32: 46049 | L32: Deni | M32: WA | N32: 46049 | O32: 46049 | Q32: Transfer | AD32: =SUM(R32:AC32) -> 0
A33: =IF(B33="A",A32+1,0) -> 0 | B33: =IF(G33="HIJAU","A",0) -> 0 | C33: =IF(D33="B",C32+1,0) -> 1 | D33: =IF(G33="MERAH","B",0) -> B | E33: =IF(F33="C",E32+1,0) -> 0 | F33: =IF(G33=0,"C",0) -> 0 | G33: MERAH | H33: 1 | I33: KRISTALINDO KARUNIA INTERNASIONAL, PT | J33: 037/KIU/EXT/2026 | K33: 46049 | L33: Albert | M33: WA | N33: 46050 | O33: 46055 | AD33: =SUM(R33:AC33) -> 0
A34: =IF(B34="A",A33+1,0) -> 0 | B34: =IF(G34="HIJAU","A",0) -> 0 | C34: =IF(D34="B",C33+1,0) -> 2 | D34: =IF(G34="MERAH","B",0) -> B | E34: =IF(F34="C",E33+1,0) -> 0 | F34: =IF(G34=0,"C",0) -> 0 | G34: MERAH | H34: 2 | I34: LESTARI INTI AGRO, CV | J34: 045/KIU/EXT/2026 | K34: 46050 | L34: Widya | M34: WA | N34: 46051 | O34: 46051 | AD34: =SUM(R34:AC34) -> 0
A35: =IF(B35="A",A34+1,0) -> 0 | B35: =IF(G35="HIJAU","A",0) -> 0 | C35: =IF(D35="B",C34+1,0) -> 3 | D35: =IF(G35="MERAH","B",0) -> B | E35: =IF(F35="C",E34+1,0) -> 0 | F35: =IF(G35=0,"C",0) -> 0 | G35: MERAH | H35: 3 | I35: SINERGI CHEM INDONESIA, PT | J35: 028/KIU/EXT/2026 | K35: 46044 | L35: Adhika | M35: WA | N35: 46044 | P35: 0.005 | Q35: Thripmat | AD35: =SUM(R35:AC35) -> 0
A36: =IF(B36="A",A35+1,0) -> 0 | B36: =IF(G36="HIJAU","A",0) -> 0 | C36: =IF(D36="B",C35+1,0) -> 0 | D36: =IF(G36="MERAH","B",0) -> 0 | E36: =IF(F36="C",E35+1,0) -> 1 | F36: =IF(G36=0,"C",0) -> C | H36: 1 | I36: ADIL MAKMUR FAJAR, PT | J36: 001/KIU/EXT/2026 | K36: 46034 | L36: Edy | M36: WA | N36: 46035 | O36: 46035 | AD36: =SUM(R36:AC36) -> 0
A37: =IF(B37="A",A36+1,0) -> 0 | B37: =IF(G37="HIJAU","A",0) -> 0 | C37: =IF(D37="B",C36+1,0) -> 0 | D37: =IF(G37="MERAH","B",0) -> 0 | E37: =IF(F37="C",E36+1,0) -> 2 | F37: =IF(G37=0,"C",0) -> C | H37: 8 | I37: AGROMANNA JAYA LESTARI, PT | J37: 014/KIU/EXT/2026 | K37: 46044 | L37: Lily | M37: WA | N37: 46044 | O37: 46044 | AD37: =SUM(R37:AC37) -> 0
A38: =IF(B38="A",A37+1,0) -> 0 | B38: =IF(G38="HIJAU","A",0) -> 0 | C38: =IF(D38="B",C37+1,0) -> 0 | D38: =IF(G38="MERAH","B",0) -> 0 | E38: =IF(F38="C",E37+1,0) -> 3 | F38: =IF(G38=0,"C",0) -> C | H38: 9 | I38: ALFA BETA AGROCHEMICAL, PT | J38: 003/KIU/EXT/2026 | K38: 46037 | L38: Iqbal | M38: WA | N38: 46037 | O38: 46062 | Q38: 09/02 pak saat ini Mr Wesley sedang di China, nanti ketika sudah di Indonesia saya update reviewnya ya pak | AD38: =SUM(R38:AC38) -> 0
A39: =IF(B39="A",A38+1,0) -> 0 | B39: =IF(G39="HIJAU","A",0) -> 0 | C39: =IF(D39="B",C38+1,0) -> 0 | D39: =IF(G39="MERAH","B",0) -> 0 | E39: =IF(F39="C",E38+1,0) -> 4 | F39: =IF(G39=0,"C",0) -> C | H39: 13 | I39: BAYER INDONESIA, PT | J39: 033/KIU/EXT/2026 | K39: 46049 | L39: Herlis/Danu | M39: email & WA | N39: 46049 | O39: 46049 | AD39: =SUM(R39:AC39) -> 0
A40: =IF(B40="A",A39+1,0) -> 0 | B40: =IF(G40="HIJAU","A",0) -> 0 | C40: =IF(D40="B",C39+1,0) -> 0 | D40: =IF(G40="MERAH","B",0) -> 0 | E40: =IF(F40="C",E39+1,0) -> 5 | F40: =IF(G40=0,"C",0) -> C | H40: 14 | I40: BAYER SEEDS INDONESIA, PT | J40: 034/KIU/EXT/2026 | K40: 46049 | L40: Martin / Wahyu | M40: WA | N40: 46050 | O40: 46055 | AD40: =SUM(R40:AC40) -> 0
A41: =IF(B41="A",A40+1,0) -> 0 | B41: =IF(G41="HIJAU","A",0) -> 0 | C41: =IF(D41="B",C40+1,0) -> 0 | D41: =IF(G41="MERAH","B",0) -> 0 | E41: =IF(F41="C",E40+1,0) -> 6 | F41: =IF(G41=0,"C",0) -> C | H41: 17 | I41: BISI INTERNATIONAL, TBK - CORN | J41: 017/KIU/EXT/2026 | K41: 46044 | L41: Nugroho | M41: WA | N41: 46044 | O41: 46044 | AD41: =SUM(R41:AC41) -> 0
A42: =IF(B42="A",A41+1,0) -> 0 | B42: =IF(G42="HIJAU","A",0) -> 0 | C42: =IF(D42="B",C41+1,0) -> 0 | D42: =IF(G42="MERAH","B",0) -> 0 | E42: =IF(F42="C",E41+1,0) -> 7 | F42: =IF(G42=0,"C",0) -> C | H42: 18 | I42: CATUR AGRODAYA MANDIRI, PT | J42: 035/KIU/EXT/2026 | K42: 46049 | L42: Kambali | M42: WA | N42: 46049 | O42: 46049 | Q42: 06/03 blm dibaca | AD42: =SUM(R42:AC42) -> 0
A43: =IF(B43="A",A42+1,0) -> 0 | B43: =IF(G43="HIJAU","A",0) -> 0 | C43: =IF(D43="B",C42+1,0) -> 0 | D43: =IF(G43="MERAH","B",0) -> 0 | E43: =IF(F43="C",E42+1,0) -> 8 | F43: =IF(G43=0,"C",0) -> C | H43: 19 | I43: CORTEVA AGRISCIENCE INDONESIA, PT | J43: 036/KIU/EXT/2026 | K43: 46049 | L43: Arief / Iwan | M43: WA | N43: 46050 | O43: 46050 | AD43: =SUM(R43:AC43) -> 0
...

Sheet Sheet3
B1: DAFTAR HASIL KONFIRMASI PROPOSAL EXTRAVAGANZA
A3: NAMA SUPLIER | D3: NAMA SUPLIER | G3: NAMA SUPLIER
A4: 1 | B4: =IFERROR(VLOOKUP(A4,Sheet1!$A$7:$I$59,9,0),"") -> AGRO GUNA MAKMUR, PT | D4: 1 | E4: =IFERROR(VLOOKUP(D4,Sheet1!$C$7:$I$59,7,0),"") -> KRISTALINDO KARUNIA INTERNASIONAL, PT | G4: 1 | H4: =IFERROR(VLOOKUP(G4,Sheet1!$E$7:$I$59,5,0),"") -> ADIL MAKMUR FAJAR, PT
A5: 2 | B5: =IFERROR(VLOOKUP(A5,Sheet1!$A$7:$I$59,9,0),"") -> AGRO NATURAL TECHNOLOGY, PT | D5: 2 | E5: =IFERROR(VLOOKUP(D5,Sheet1!$C$7:$I$59,7,0),"") -> LESTARI INTI AGRO, CV | G5: 2 | H5: =IFERROR(VLOOKUP(G5,Sheet1!$E$7:$I$59,5,0),"") -> AGROMANNA JAYA LESTARI, PT
A6: 3 | B6: =IFERROR(VLOOKUP(A6,Sheet1!$A$7:$I$59,9,0),"") -> BASF DISTRIBUTION INDONESIA, PT | D6: 3 | E6: =IFERROR(VLOOKUP(D6,Sheet1!$C$7:$I$59,7,0),"") -> SINERGI CHEM INDONESIA, PT | G6: 3 | H6: =IFERROR(VLOOKUP(G6,Sheet1!$E$7:$I$59,5,0),"") -> ALFA BETA AGROCHEMICAL, PT
A7: 4 | B7: =IFERROR(VLOOKUP(A7,Sheet1!$A$7:$I$59,9,0),"") -> BENIH CITRA ASIA, PT | D7: 4 | E7: =IFERROR(VLOOKUP(D7,Sheet1!$C$7:$I$59,7,0),"") | G7: 4 | H7: =IFERROR(VLOOKUP(G7,Sheet1!$E$7:$I$59,5,0),"") -> BAYER INDONESIA, PT
A8: 5 | B8: =IFERROR(VLOOKUP(A8,Sheet1!$A$7:$I$59,9,0),"") -> JAVA KARLOS INDONESIA, PT | D8: 5 | E8: =IFERROR(VLOOKUP(D8,Sheet1!$C$7:$I$59,7,0),"") | G8: 5 | H8: =IFERROR(VLOOKUP(G8,Sheet1!$E$7:$I$59,5,0),"") -> BAYER SEEDS INDONESIA, PT
A9: 6 | B9: =IFERROR(VLOOKUP(A9,Sheet1!$A$7:$I$59,9,0),"") -> MITRA KREASI DHARMA, PT | D9: 6 | E9: =IFERROR(VLOOKUP(D9,Sheet1!$C$7:$I$59,7,0),"") | G9: 6 | H9: =IFERROR(VLOOKUP(G9,Sheet1!$E$7:$I$59,5,0),"") -> BISI INTERNATIONAL, TBK - CORN
A10: 7 | B10: =IFERROR(VLOOKUP(A10,Sheet1!$A$7:$I$59,9,0),"") -> MITRA TANI ABADI JAYA, CV | D10: 7 | E10: =IFERROR(VLOOKUP(D10,Sheet1!$C$7:$I$59,7,0),"") | G10: 7 | H10: =IFERROR(VLOOKUP(G10,Sheet1!$E$7:$I$59,5,0),"") -> CATUR AGRODAYA MANDIRI, PT
A11: 8 | B11: =IFERROR(VLOOKUP(A11,Sheet1!$A$7:$I$59,9,0),"") -> NUFARM INDONESIA, PT | D11: 8 | E11: =IFERROR(VLOOKUP(D11,Sheet1!$C$7:$I$59,7,0),"") | G11: 8 | H11: =IFERROR(VLOOKUP(G11,Sheet1!$E$7:$I$59,5,0),"") -> CORTEVA AGRISCIENCE INDONESIA, PT
A12: 9 | B12: =IFERROR(VLOOKUP(A12,Sheet1!$A$7:$I$59,9,0),"") -> SINAR GENERAL INDUSTRIES, PT | D12: 9 | E12: =IFERROR(VLOOKUP(D12,Sheet1!$C$7:$I$59,7,0),"") | G12: 9 | H12: =IFERROR(VLOOKUP(G12,Sheet1!$E$7:$I$59,5,0),"") -> INTER AGRO INDONESIA, PT
A13: 10 | B13: =IFERROR(VLOOKUP(A13,Sheet1!$A$7:$I$59,9,0),"") -> SONGGOLANGIT PERSADA - DENPASAR | D13: 10 | E13: =IFERROR(VLOOKUP(D13,Sheet1!$C$7:$I$59,7,0),"") | G13: 10 | H13: =IFERROR(VLOOKUP(G13,Sheet1!$E$7:$I$59,5,0),"") -> JAWA AGRINDO INTERNASIONAL, PT
A14: 11 | B14: =IFERROR(VLOOKUP(A14,Sheet1!$A$7:$I$59,9,0),"") -> TANI ABADI, CV | D14: 11 | E14: =IFERROR(VLOOKUP(D14,Sheet1!$C$7:$I$59,7,0),"") | G14: 11 | H14: =IFERROR(VLOOKUP(G14,Sheet1!$E$7:$I$59,5,0),"") -> KENSO INDONESIA, PT
A15: 12 | B15: =IFERROR(VLOOKUP(A15,Sheet1!$A$7:$I$59,9,0),"") -> ASIANA CHEMICALINDO LESTARI, PT | D15: 12 | E15: =IFERROR(VLOOKUP(D15,Sheet1!$C$7:$I$59,7,0),"") | G15: 12 | H15: =IFERROR(VLOOKUP(G15,Sheet1!$E$7:$I$59,5,0),"") -> OAT MITOKU AGRIO, PT
... A40: 37 | B40: =IFERROR(VLOOKUP(A40,Sheet1!$A$7:$I$59,9,0),"") | D40: 37 | E40: =IFERROR(VLOOKUP(D40,Sheet1!$C$7:$I$59,7,0),"") | G40: 37 | H40: =IFERROR(VLOOKUP(G40,Sheet1!$E$7:$I$59,5,0),"")
G41: 38 | H41: =IFERROR(VLOOKUP(G41,Sheet1!$E$7:$I$59,5,0),"")
G42: 39 | H42: =IFERROR(VLOOKUP(G42,Sheet1!$E$7:$I$59,5,0),"")
G43: 40 | H43: =IFERROR(VLOOKUP(G43,Sheet1!$E$7:$I$59,5,0),"")
G44: 41 | H44: =IFERROR(VLOOKUP(G44,Sheet1!$E$7:$I$59,5,0),"")
G45: 42 | H45: =IFERROR(VLOOKUP(G45,Sheet1!$E$7:$I$59,5,0),"")
G46: 43 | H46: =IFERROR(VLOOKUP(G46,Sheet1!$E$7:$I$59,5,0),"")
G47: 44 | H47: =IFERROR(VLOOKUP(G47,Sheet1!$E$7:$I$59,5,0),"")
