Workbook
Name ch_hrgincppn: '[1]CEK Harga'!$AD$2:$AD$13259
Name ch_hrgincppn: '[2]CEK Harga'!$AD$2:$AD$13259
Name ch_kd: '[1]CEK Harga'!$W$2:$W$13259
Name ch_kd: '[2]CEK Harga'!$W$2:$W$13259
Name TBLHRG: #REF!

Sheet REVISI FAKTUR SC
B1: REKAP REVISI FAKTUR (SC) Per Barang
B2: Per Maret 2023
A4: No | B4: Tanggal Revisi | C4: Tanggal Faktur | D4: No. Faktur | E4: SC | F4: Adm SC | G4: Cust | H4: Nama Barang | I4: Jumlah | J4: Keterangan | K4: Case | L4: Next Step
A5: 1 | B5: 44937 | C5: 44937 | D5: B23000320 | E5: Dannis | F5: Nia | G5: Santani, UD | H5: Kresnadan 3G 10 X 2 kg (edit harga jadi 27.500) | I5: 6875000 | J5: SC salah harga (harga awal 29.500)
A6: 2 | B6: 44938 | C6: 44938 | D6: D23000300 | E6: Yuyun | F6: Nina | G6: Sampurna/Heri (Kemuning) | H6: Ammate 150 EC 20 X 100 ml (FMC) (edit harga jadi 102.000) | I6: 5347000 | J6: SC salah harga (harga awal 99.000)
A7: 1 | B7: 44943 | C7: 44943 | D7: E23000478 | E7: Umi | F7: Nita | G7: Sahabat Tani, UD/Edy | H7: Amolin | I7: 10080000 | J7: Double SO | K7: SO 1 dibuat tanggal 16 (input tgl 16/01/23 jam 15.54, dan SO 2 dibuat tgl 17/01/2022 (input 17/01/2022, jam 9.06). Setiap tutup tanggal SC cek penjualannya, Double SO tersebut diketahui saat SC cek penjualannya, jadi pada saat itu juga 1 nota di Batal, sebelum nota diambil oleh gudang. | L7: Saat SC akan TTD Nota, SC juga cek antara nota dan SO, dan SC Umi sudah melakukannya, sehingga kesalahan bisa terdeteksi sebelum Nota diserahkan ke Gudang
A8: 3 | B8: 44950 | C8: 44949 | D8: C23000519 | E8: Elok | F8: Fani | G8: Barokah Tani/Syaikur | H8: Tali Gawar 989 40 X 600 gr (edit harga jadi 28.500) | I8: 8740000 | J8: SC salah harga (harga awal 38.500) | K8: Salah tulis harga di SO, seharusnya 28.500 | L8: Filter dari Acc lebih ditingkatkan, apabila harga terlalu mahal, tanyakan juga kepada SC
A9: 4 | B9: 44950 | C9: 44950 | D9: B23000779 | E9: Evi | F9: Nia | G9: Alam Tani | H9: Decis 2.5 EC 20 X 500 ml (edit harga jadi 121.500) | I9: 92300000 | J9: SC salah harga (harga awal 112.500) | K9: Salah tulis harga di SO, seharusnya 121.500 | L9: Adm PL menanyakan kepada SC ybs apabila ada acc harga yang meragukan, Revisi SOP
A10: 5 | B10: 44952 | C10: 44952 | D10: E23000777 | E10: Umi | F10: Nita | G10: Al Mubarok/Lutfi | H10: Karimazu 590 EC 20 X 800 ml (edit harga jadi 138.500) | I10: 2770000 | J10: SC salah harga (harga awal 135.000) | K10: Salah liat harga, di PL 138.500 | L10: PL digital
A11: 6 | B11: 44954 | C11: 44954 | D11: C23000675 | E11: Fani | F11: Elok | G11: Setia Hati, Toko | H11: Alfatox 50 EC 50 X 80 ml (AGM) (edit harga jadi 13.500) | I11: 1350000 | J11: SC salah harga (harga awal 18.500) | K11: SC salah harga (harga awal 18.500)
A12: 1 | B12: 44965 | C12: 44965 | D12: D23001098 | E12: Dannis | F12: Nina | G12: Puma Tani | H12: Sprayer Elektrik Joeragan 16 L Battery (edit harga jadi 410.000) | I12: 820000 | J12: SC Salah Harga | K12: SC salah Harga, harga awal 395.000, Hasil konfirmasi dengan SC : SC tidak lihat Data Price List, saat cek harga pertama sudah diingatkan kalau harga terlalu murah, tapi sampai tutup penjualan harga tetap 395.000
A13: 2 | B13: 44965 | C13: 44965 | D13: D23001115 | E13: Zakia | F13: Nina | G13: Alam Tani/Wayan | H13: Trisula 450 SL 20 X 500 ml (edit harga jadi 32.500) | I13: 4120000 | J13: SC Salah Harga | K13: SC Salah Harga, harga awal 54.500 (harga untuk Trisula 1ltr) saat cek harga 1 sudah dikonfirmasi, hasil konfirmasi menurut SC tidak masalah, saat tutup penjualan dikonfirmasi lagi dan ternyata salah harga
A14: 3 | B14: 44977 | C14: 44977 | D14: C23001323 | E14: Elok | F14: Fani | G14: Dino Vita, Toko | H14: Karissnail 6 PL 20 X 500 gr (M2U) (edit harga jadi 57.000) | I14: 2280000 | J14: SC salah harga (harga awal 25.000) | K14: Salah kasih harga yang 200 gr
A15: 1 | B15: 45002 | C15: 45000 | D15: B23002204 | E15: Zakia | F15: Nia | G15: Sukma Tani | H15: Mulsa Ori Universal 0.25 60 cm X 18 kg (Roll) (edit harga jadi 567.000) | I15: 28721550 | J15: SC salah harga (harga awal 603.000) | K15: SC Salah beri harga sama dengan Mulsa Karisma
A31: 1
B34: REVISI FAKTUR BERDASARKAN SC (Salah Harga) | R34: REVISI FAKTUR BERDASARKAN SC (Salah SO)
B35: Periode Januari - Maret 2023 | R35: Periode Januari 2023
B36: SC | C36: Jan | D36: Feb | E36: Mar | F36: Apr | G36: Mei | H36: Jun | I36: Jul | J36: Agst | K36: Sept | L36: Okt | M36: Nov | N36: Des | O36: Total | P36: % | R36: SC | S36: Jan | T36: Feb | U36: Mar | V36: Apr | W36: Mei | X36: Jun | Y36: Jul | Z36: Agst | AA36: Sept | AB36: Okt | AC36: Nov | AD36: Des | AE36: Total | AF36: %
B37: Dannis | C37: 1 | D37: 1 | O37: =SUM(C37:N37) -> 2 | P37: =+O37/#REF! -> #REF! | R37: Dannis | AE37: =SUM(S37:AD37) -> 0 | AF37: =AE37/O49 -> 0
B38: Elok | C38: 2 | D38: 1 | O38: =SUM(C38:N38) -> 3 | P38: =+O38/#REF! -> #REF! | R38: Elok | AE38: =SUM(S38:AD38) -> 0 | AF38: =AE38/O50 -> 0
B39: Evi | C39: 1 | O39: =SUM(C39:N39) -> 1 | P39: =+O39/#REF! -> #REF! | R39: Evi | AE39: =SUM(S39:AD39) -> 0 | AF39: =AE39/O51 -> 0
B40: Faisal | O40: =SUM(C40:N40) -> 0 | P40: =+O40/#REF! -> #REF! | R40: Faisal | AE40: =SUM(S40:AD40) -> 0 | AF40: =AE40/O52 -> 0
B41: Riyan | O41: =SUM(C41:N41) -> 0 | P41: =+O41/#REF! -> #REF! | R41: Riyan | AE41: =SUM(S41:AD41) -> 0 | AF41: =AE41/O53 -> 0
B42: Umi | C42: 1 | O42: =SUM(C42:N42) -> 1 | P42: =+O42/#REF! -> #REF! | R42: Umi | S42: 1 | AE42: =SUM(S42:AD42) -> 1 | AF42: =AE42/O54 -> 0.00039872408
B43: Yuyun | C43: 1 | O43: =SUM(C43:N43) -> 1 | P43: =+O43/#REF! -> #REF! | R43: Yuyun | AE43: =SUM(S43:AD43) -> 0 | AF43: =AE43/O55 -> 0
B44: Zakia | D44: 1 | E44: 1 | O44: =SUM(C44:N44) -> 2 | P44: =+O44/#REF! -> #REF! | R44: Zakia | AE44: =SUM(S44:AD44) -> 0 | AF44: =AE44/O56 -> 0
B45: Grand Total | C45: =SUM(C37:C44) -> 6 | D45: =SUM(D37:D44) -> 3 | E45: =SUM(E37:E44) -> 1 | F45: =SUM(F37:F44) -> 0 | G45: =SUM(G37:G44) -> 0 | H45: =SUM(H37:H44) -> 0 | I45: =SUM(I37:I44) -> 0 | J45: =SUM(J37:J44) -> 0 | ... P45: =SUM(P37:P44) -> #REF! | R45: Grand Total | S45: =SUM(S37:S44) -> 1 | T45: =SUM(T37:T44) -> 0 | U45: =SUM(U37:U44) -> 0 | V45: =SUM(V37:V44) -> 0 | W45: =SUM(W37:W44) -> 0 | X45: =SUM(X37:X44) -> 0 | Y45: =SUM(Y37:Y44) -> 0 | Z45: =SUM(Z37:Z44) -> 0 | ... AE45: =SUM(AE37:AE44) -> 1
B46: JUMLAH Per Barang yang Tertera di SO
B47: JUMLAH Per Barang yang Tertera di SO
B48: SC | C48: Jan | D48: Feb | E48: Mar | F48: Apr | G48: Mei | H48: Jun | I48: Jul | J48: Agst | K48: Sept | L48: Okt | M48: Nov | N48: Des | O48: Total
B49: Dannis | C49: 311 | D49: 316 | E49: 215 | O49: =SUM(C49:N49) -> 842
B50: Elok | C50: 1841 | D50: 1656 | E50: 1270 | O50: =SUM(C50:N50) -> 4767
B51: Evi | C51: 794 | D51: 691 | E51: 479 | O51: =SUM(C51:N51) -> 1964
B52: Faisal | C52: 197 | D52: 168 | E52: 114 | O52: =SUM(C52:N52) -> 479
B53: Riyan | C53: 562 | D53: 620 | E53: 421 | O53: =SUM(C53:N53) -> 1603
B54: Umi | C54: 1021 | D54: 905 | E54: 582 | O54: =SUM(C54:N54) -> 2508
B55: Yuyun | C55: 1387 | D55: 1338 | E55: 1090 | O55: =SUM(C55:N55) -> 3815
B56: Zakia | C56: 1116 | D56: 1085 | E56: 766 | O56: =SUM(C56:N56) -> 2967
B57: Supriyanto/Nadia | C57: 3 | D57: 8 | O57: =SUM(C57:N57) -> 11
B58: Others | O58: =SUM(C58:N58) -> 0
...

Sheet REVISI Per Brg ADM SC
A2: REKAP REVISI FAKTUR (Admin SC) Berdasarkan Jumlah Barang
A3: Per Maret 2023
A5: No | B5: Tanggal Revisi | C5: Tanggal Faktur | D5: No. Faktur | E5: Admin SC | F5: SC | G5: Cust | H5: Nama Barang | I5: Jumlah | J5: Keterangan | K5: Case | L5: Next Step | M5: Next Step (Saran)
A6: 1 | B6: 44937 | C6: 44937 | D6: D23000279 | E6: Evi | F6: Nina | G6: KIU Cabang | H6: Bionik 400 EC 20 X 500 ml (hapus VAT) | I6: 21813168 | J6: Admin salah input | K6: Salah Input VAT, seharusnya KIU Cabang tanpa VAT
A7: 1 | B7: 44970 | C7: 44970 | D7: C23001070 | E7: Umi | F7: Fani | G7: Sahala/Syaiful | H7: Batal | I7: 9925000 | J7: admin salah input, Cust TL Pajak | K7: Salah input cust Tidak Lapor Pajak seharusnya di nota Z tapi dibukakan nota komersil
A8: 1
B31: REVISI FAKTUR BERDASARKAN ADMIN SC
B32: Periode Januari-Februari 2023
B33: Adm. SC | C33: Jan | D33: Feb | E33: Mar | F33: Apr | G33: Mei | H33: Jun | I33: Jul | J33: Agst | K33: Sept | L33: Okt | M33: Nov | N33: Des | O33: Total
B34: Fani | D34: 2 | O34: =SUM(C34:N34) -> 2
B35: Nia | O35: =SUM(C35:N35) -> 0
B36: Nina | C36: 1 | O36: =SUM(C36:N36) -> 1
B37: Nita | O37: =SUM(C37:N37) -> 0
B38: Grand Total | C38: =SUM(C34:C37) -> 1 | D38: =SUM(D34:D37) -> 2 | E38: =SUM(E34:E37) -> 0 | F38: =SUM(F34:F37) -> 0 | G38: =SUM(G34:G37) -> 0 | H38: =SUM(H34:H37) -> 0 | I38: =SUM(I34:I37) -> 0 | J38: =SUM(J34:J37) -> 0 | ... O38: =SUM(O34:O37) -> 3
B39: JUMLAH INPUT BARANG
B40: Adm. SC | C40: Jan | D40: Feb | E40: Mar | F40: Apr | G40: Mei | H40: Jun | I40: Jul | J40: Agst | K40: Sept | L40: Okt | M40: Nov | N40: Des | O40: Total
B41: Fani | C41: 1420 | D41: 1799 | E41: 1154 | O41: =SUM(C41:N41) -> 4373
B42: Nia | C42: 2113 | D42: 1431 | E42: 1808 | O42: =SUM(C42:N42) -> 5352
B43: Nina | C43: 1702 | D43: 2572 | E43: 1826 | O43: =SUM(C43:N43) -> 6100
B44: Nita | C44: 1801 | D44: 811 | O44: =SUM(C44:N44) -> 2612
B45: Mitra | C45: 192 | D45: 172 | E45: 136 | O45: =SUM(C45:N45) -> 500
B46: Ifa | C46: 4 | D46: 8 | E46: 13 | O46: =SUM(C46:N46) -> 25
B47: Grand | C47: =SUM(C41:C46) -> 7232 | D47: =SUM(D41:D46) -> 6793 | E47: =SUM(E41:E46) -> 4937 | F47: =SUM(F41:F46) -> 0 | G47: =SUM(G41:G46) -> 0 | H47: =SUM(H41:H46) -> 0 | I47: =SUM(I41:I46) -> 0 | J47: =SUM(J41:J46) -> 0 | ... O47: =SUM(O41:O46) -> 18962
B48: % REVISI FAKTUR TERHADAP TOTAL INPUT BARANG
B49: Adm. SC | C49: Jan | D49: Feb | E49: Mar | F49: Apr | G49: Mei | H49: Jun | I49: Jul | J49: Agst | K49: Sept | L49: Okt | M49: Nov | N49: Des | O49: Total
B50: Fani | C50: =+C34/C41 -> 0 | D50: =+D34/D41 -> 0.0011117287 | E50: =+E34/E41 -> 0 | F50: =+F34/F41 -> #DIV/0! | G50: =+G34/G41 -> #DIV/0! | H50: =+H34/H41 -> #DIV/0! | I50: =+I34/I41 -> #DIV/0! | J50: =+J34/J41 -> #DIV/0! | ... O50: =+O34/O41 -> 0.00045735193
B51: Nia | C51: =+C35/C42 -> 0 | D51: =+D35/D42 -> 0 | E51: =+E35/E42 -> 0 | F51: =+F35/F42 -> #DIV/0! | G51: =+G35/G42 -> #DIV/0! | H51: =+H35/H42 -> #DIV/0! | I51: =+I35/I42 -> #DIV/0! | J51: =+J35/J42 -> #DIV/0! | ... O51: =+O35/O42 -> 0
B52: Nina | C52: =+C36/C43 -> 0.00058754407 | D52: =+D36/D43 -> 0 | E52: =+E36/E43 -> 0 | F52: =+F36/F43 -> #DIV/0! | G52: =+G36/G43 -> #DIV/0! | H52: =+H36/H43 -> #DIV/0! | I52: =+I36/I43 -> #DIV/0! | J52: =+J36/J43 -> #DIV/0! | ... O52: =+O36/O43 -> 0.00016393443
B53: Nita | C53: =+C37/C44 -> 0 | D53: =+D37/D44 -> 0 | E53: =+E37/E44 -> #DIV/0! | F53: =+F37/F44 -> #DIV/0! | G53: =+G37/G44 -> #DIV/0! | H53: =+H37/H44 -> #DIV/0! | I53: =+I37/I44 -> #DIV/0! | J53: =+J37/J44 -> #DIV/0! | ... O53: =+O37/O44 -> 0
B54: Grand Total | C54: =+C38/C47 -> 0.00013827434 | D54: =+D38/D47 -> 0.00029442073 | E54: =+E38/E47 -> 0 | F54: =+F38/F47 -> #DIV/0! | G54: =+G38/G47 -> #DIV/0! | H54: =+H38/H47 -> #DIV/0! | I54: =+I38/I47 -> #DIV/0! | J54: =+J38/J47 -> #DIV/0! | ... O54: =+O38/O47 -> 0.00015821116

Sheet REVISI PER FAKTUR ADM SC
A2: REKAP REVISI FAKTUR (Admin SC) Berdasarkan Jumlah Faktur
A3: Per Oktober 2022
A5: No | B5: Tanggal Revisi | C5: Tanggal Faktur | D5: No. Faktur | E5: Admin SC | F5: Cust | G5: Keterangan | H5: Jumlah | I5: Keterangan | J5: Case | K5: Next Step
A6: 1 | B6: 44837 | C6: 44835 | D6: D22007033 | E6: Nina | F6: Sadar Sari/Farid Firdaus | G6: Sprayer 5 lt ganti yg 10 ltr | H6: 0 | I6: Admin salah Input | J6: Salah input barang, | K6: Konfirmasi kepada Adm SC ybc, salah input seharusnya yg 10ltr, memberitahukan progres revisi faktur per 15/10/2022
A7: 2 | B7: 44845 | C7: 44845 | D7: B22007412 | E7: Nia | F7: M. Tajudin Al Fajri/Indotani | G7: Monkey 40 SP 100 X 100 gr (EDIT HARGA JADI 18.500) harga sebelumnya 18.000 | H7: 1850000 | I7: Admin salah Input | J7: Admin konfrimasi via telp, salah input harga
A8: 3 | B8: 44853 | C8: 44853 | D8: D22007471 | E8: Nina | F8: KIU Cabang | G8: Biggrow 20 WP 4 X 75 X 5 gr (edit harga 17.597.61) | H8: 100510775 | I8: Admin salah input VAT | J8: Admin Salah Input nota KIU Cabang Inc PPN, KIU Cabang seharusnya diinput tanpa pajak
E9: Nina | F9: KIU Cabang | G9: Bactocyn 150 AL 50 X 200 ml (edit harga 27.654.04) | H9: 100510775 | I9: Admin salah input VAT
E10: Nina | F10: KIU Cabang | G10: Lem Ajaib 50 X 100 ml (edit harga 41.418.21) | H10: 100510775 | I10: Admin salah input VAT
E11: Nina | F11: KIU Cabang | G11: Karissnail 6 PL 20 X 500 gr (M2U) (edit harga 26.363.64) | H11: 100510775 | I11: Admin salah input VAT
A12: 4 | B12: 44856 | C12: 44855 | D12: B22007566 | E12: Nia | F12: Maju Mandiri/Sunardi | G12: BATAL | H12: 950000 | I12: Admin salah input nama cust | J12: Salah Input nama toko seharusnya Sukses Makmur Sunardi, tapi diinput Maju Mandiri/Sunardi
A13: 5 | B13: 44860 | C13: 44859 | D13: O22000085 | E13: Nita | F13: Trubus Jaya/Deni | G13: BATAL | H13: 136500 | I13: Admin salah input
A14: 6 | B14: 44861 | C14: 44856 | D14: B22007577 | E14: Nia | F14: Febri Catur Nugroho | G14: BATAL | H14: 3300000 | I14: Barang diretur, karena admin salah input | J14: Admin salah input, harusnya Cal. D.diana, 0,01/09/2027
A15: 7 | B15: 44863 | C15: 44858 | D15: C22007261 | E15: Fani | F15: Bimo Rukun Tani II | G15: Timun Renes F1 12 X 15 X 10 gr (edit yg Qty 15 di diskon) | H15: 10860000 | I15: Admin salah input | J15: Nota awal Bonus tidak diberi diskon
B23: REVISI FAKTUR BERDASARKAN ADMIN SC
B24: Periode Januari - 29 Oktober 2022
B25: Adm. SC | C25: Jan | D25: Feb | E25: Mar | F25: Apr | G25: Mei | H25: Jun | I25: Jul | J25: Agst | K25: Sept | L25: Okt | M25: Nov | N25: Des | O25: Total
B26: Fani | C26: 14 | D26: 7 | E26: 12 | F26: 13 | G26: 8 | H26: 5 | I26: 0 | J26: 4 | K26: 1 | L26: 1 | O26: =SUM(C26:N26) -> 65
B27: Naily | C27: 2 | D27: 1 | E27: 0 | F27: 0 | G27: 0 | K27: 0 | O27: =SUM(C27:N27) -> 3
B28: Nia | C28: 3 | D28: 2 | E28: 5 | F28: 0 | G28: 1 | H28: 1 | I28: 0 | J28: 0 | K28: 1 | L28: 3 | O28: =SUM(C28:N28) -> 16
B29: Nina | C29: 4 | D29: 1 | E29: 9 | F29: 2 | G29: 1 | H29: 2 | I29: 3 | J29: 4 | K29: 2 | L29: 2 | O29: =SUM(C29:N29) -> 30
B30: Nita | C30: 3 | D30: 1 | E30: 3 | F30: 7 | G30: 3 | H30: 4 | I30: 4 | J30: 6 | K30: 1 | L30: 1 | O30: =SUM(C30:N30) -> 33
B31: Grand Total | C31: =SUM(C26:C30) -> 26 | D31: =SUM(D26:D30) -> 12 | E31: =SUM(E26:E30) -> 29 | F31: =SUM(F26:F30) -> 22 | G31: =SUM(G26:G30) -> 13 | H31: =SUM(H26:H30) -> 12 | I31: =SUM(I26:I30) -> 7 | J31: =SUM(J26:J30) -> 14 | ... O31: =SUM(O26:O30) -> 147
B32: JUMLAH PRODUKSI FAKTUR
B33: Adm. SC | C33: Jan | D33: Feb | E33: Mar | F33: Apr | G33: Mei | H33: Jun | I33: Jul | J33: Agst | K33: Sept | L33: Okt | M33: Nov | N33: Des | O33: Total
B34: Fani | C34: 634 | D34: 667 | E34: 1048 | F34: 725 | G34: 734 | H34: 896 | I34: 914 | J34: 851 | K34: 881 | L34: 758 | O34: =SUM(C34:N34) -> 8108
B35: Ex Naily | C35: 806 | D35: 458 | E35: 0 | F35: 0 | G35: 0 | H35: 0 | I35: 0 | J35: 0 | O35: =SUM(C35:N35) -> 1264
B36: Nia | C36: 1011 | D36: 844 | E36: 1086 | F36: 640 | G36: 755 | H36: 738 | I36: 935 | J36: 949 | K36: 926 | L36: 575 | O36: =SUM(C36:N36) -> 8459
B37: Nina | C37: 834 | D37: 694 | E37: 1195 | F37: 633 | G37: 729 | H37: 952 | I37: 791 | J37: 948 | K37: 832 | L37: 884 | O37: =SUM(C37:N37) -> 8492
B38: Nita | C38: 810 | D38: 610 | E38: 809 | F38: 1167 | G38: 746 | H38: 1022 | I38: 809 | J38: 1230 | K38: 1002 | L38: 975 | O38: =SUM(C38:N38) -> 9180
B39: Ifa | C39: 4 | E39: 2 | F39: 1 | G39: 1 | H39: 2 | I39: 5 | J39: 6 | K39: 2 | O39: =SUM(C39:N39) -> 23
B40: Diana | F40: 1 | O40: =SUM(C40:N40) -> 1
B41: Grand | C41: =SUM(C34:C40) -> 4099 | D41: =SUM(D34:D40) -> 3273 | E41: =SUM(E34:E40) -> 4140 | F41: =SUM(F34:F40) -> 3167 | G41: =SUM(G34:G40) -> 2965 | H41: =SUM(H34:H40) -> 3610 | I41: =SUM(I34:I40) -> 3454 | J41: =SUM(J34:J40) -> 3984 | K41: =SUM(K34:K40) -> 3643 | L41: =SUM(L34:L38) -> 3192 | M41: =SUM(M34:M38) -> 0 | N41: =SUM(N34:N38) -> 0 | O41: =SUM(O34:O40) -> 35527
B42: % REVISI FAKTUR TERHADAP TOTAL FAKTUR
B43: Adm. SC | C43: Jan | D43: Feb | E43: Mar | F43: Apr | G43: Mei | H43: Jun | I43: Jul | J43: Agst | K43: Sept | L43: Okt | M43: Nov | N43: Des | O43: Total
B44: Fani | C44: =+C26/C34 -> 0.022082019 | D44: =+D26/D34 -> 0.010494753 | E44: =+E26/E34 -> 0.011450382 | F44: =+F26/F34 -> 0.017931034 | G44: =+G26/G34 -> 0.010899183 | H44: =+H26/H34 -> 0.0055803571 | I44: =+I26/I34 -> 0 | J44: =+J26/J34 -> 0.0047003525 | ... O44: =+O26/O34 -> 0.0080167736
B45: Naily | C45: =+C27/C35 -> 0.0024813896 | D45: =+D27/D35 -> 0.0021834061 | E45: 0 | F45: 0 | G45: 0 | H45: 0 | I45: =+I27/I35 -> #DIV/0! | J45: =+J27/J35 -> #DIV/0! | K45: =+K27/K35 -> #DIV/0! | L45: =+L27/L35 -> #DIV/0! | M45: =+M27/M35 -> #DIV/0! | N45: =+N27/N35 -> #DIV/0! | O45: =+O27/O35 -> 0.0023734177
B46: Nia | C46: =+C28/C36 -> 0.0029673591 | D46: =+D28/D36 -> 0.0023696682 | E46: =+E28/E36 -> 0.0046040516 | F46: =+F28/F36 -> 0 | G46: =+G28/G36 -> 0.0013245033 | H46: =+H28/H36 -> 0.0013550136 | I46: =+I28/I36 -> 0 | J46: =+J28/J36 -> 0 | ... O46: =+O28/O36 -> 0.0018914765
B47: Nina | C47: =+C29/C37 -> 0.0047961631 | D47: =+D29/D37 -> 0.0014409222 | E47: =+E29/E37 -> 0.0075313808 | F47: =+F29/F37 -> 0.0031595577 | G47: =+G29/G37 -> 0.0013717421 | H47: =+H29/H37 -> 0.0021008403 | I47: =+I29/I37 -> 0.0037926675 | J47: =+J29/J37 -> 0.0042194093 | ... O47: =+O29/O37 -> 0.0035327367
B48: Nita | C48: =+C30/C38 -> 0.0037037037 | D48: =+D30/D38 -> 0.0016393443 | E48: =+E30/E38 -> 0.0037082818 | F48: =+F30/F38 -> 0.0059982862 | G48: =+G30/G38 -> 0.0040214477 | H48: =+H30/H38 -> 0.0039138943 | I48: =+I30/I38 -> 0.0049443758 | J48: =+J30/J38 -> 0.0048780488 | ... O48: =+O30/O38 -> 0.0035947712
B49: Grand Total | C49: =+C31/C41 -> 0.0063430105 | D49: =+D31/D41 -> 0.0036663611 | E49: =+E31/E41 -> 0.0070048309 | F49: =+F31/F41 -> 0.0069466372 | G49: =+G31/G41 -> 0.0043844857 | H49: =+H31/H41 -> 0.0033240997 | I49: =+I31/I41 -> 0.0020266358 | J49: =+J31/J41 -> 0.0035140562 | ... O49: =+O31/O41 -> 0.0041376981

Sheet REVISI FAKTUR LOG
B1: REKAP REVISI FAKTUR (Logistik)
B2: 2023
A4: No | B4: Tanggal Revisi | C4: Tanggal Faktur | D4: No. Faktur | E4: Cust | F4: Keterangan | G4: Jumlah | H4: Keterangan | I4: Ket P. Bayu/P.Alif | J4: Driver | K4: Helper
B5: 44936 | C5: 44921 | D5: B22009209 | E5: Mitra Tani, UD/Gunawan | F5: batal | G5: 1545000 | H5: terlalu lama kirim

Sheet REKAP (Faktur)
B2: REVISI FAKTUR BERDASARKAN ALASANNYA
B3: Periode Januari - 30 Mei 2026
B4: Klasifikasi | C4: Januari | D4: Februari | E4: Maret | F4: April | G4: Mei | H4: Juni | I4: Juli | J4: Agustus | K4: September | L4: Oktober | M4: November | N4: Desember | O4: Total | Q4: 2025 | R4: Diff
B5: Permintaan Cust (Ganti Kemasan, Ganti Identitas Pajak, Habis Musim, Ganti Qty) | C5: =COUNTIFS('Data (Per Faktur)'!$A:$A,'REKAP (Faktur)'!C$4,'Data (Per Faktur)'!$K:$K,'REKAP (Faktur)'!$B5) -> 2 | D5: =COUNTIFS('Data (Per Faktur)'!$A:$A,'REKAP (Faktur)'!D$4,'Data (Per Faktur)'!$K:$K,'REKAP (Faktur)'!$B5) -> 4 | E5: =COUNTIFS('Data (Per Faktur)'!$A:$A,'REKAP (Faktur)'!E$4,'Data (Per Faktur)'!$K:$K,'REKAP (Faktur)'!$B5) -> 3 | F5: =COUNTIFS('Data (Per Faktur)'!$A:$A,'REKAP (Faktur)'!F$4,'Data (Per Faktur)'!$K:$K,'REKAP (Faktur)'!$B5) -> 5 | G5: =COUNTIFS('Data (Per Faktur)'!$A:$A,'REKAP (Faktur)'!G$4,'Data (Per Faktur)'!$K:$K,'REKAP (Faktur)'!$B5) -> 4 | H5: =COUNTIFS('Data (Per Faktur)'!$A:$A,'REKAP (Faktur)'!H$4,'Data (Per Faktur)'!$K:$K,'REKAP (Faktur)'!$B5) -> 0 | I5: =COUNTIFS('Data (Per Faktur)'!$A:$A,'REKAP (Faktur)'!I$4,'Data (Per Faktur)'!$K:$K,'REKAP (Faktur)'!$B5) -> 0 | J5: =COUNTIFS('Data (Per Faktur)'!$A:$A,'REKAP (Faktur)'!J$4,'Data (Per Faktur)'!$K:$K,'REKAP (Faktur)'!$B5) -> 0 | ... N5: =COUNTIFS('Data (Per Faktur)'!$A:$A,'REKAP (Faktur)'!N$4,'Data (Per Faktur)'!$K:$K,'REKAP (Faktur)'!$B5) -> 0 | O5: =SUM(C5:N5) -> 18 | Q5: 53 | R5: =+O5-Q5 -> -35
B6: Lain - Lain (Acc oleh Direktur, Hpp berubah) | C6: =COUNTIFS('Data (Per Faktur)'!$A:$A,'REKAP (Faktur)'!C$4,'Data (Per Faktur)'!$K:$K,'REKAP (Faktur)'!$B6) -> 1 | D6: =COUNTIFS('Data (Per Faktur)'!$A:$A,'REKAP (Faktur)'!D$4,'Data (Per Faktur)'!$K:$K,'REKAP (Faktur)'!$B6) -> 0 | E6: =COUNTIFS('Data (Per Faktur)'!$A:$A,'REKAP (Faktur)'!E$4,'Data (Per Faktur)'!$K:$K,'REKAP (Faktur)'!$B6) -> 0 | F6: =COUNTIFS('Data (Per Faktur)'!$A:$A,'REKAP (Faktur)'!F$4,'Data (Per Faktur)'!$K:$K,'REKAP (Faktur)'!$B6) -> 0 | G6: =COUNTIFS('Data (Per Faktur)'!$A:$A,'REKAP (Faktur)'!G$4,'Data (Per Faktur)'!$K:$K,'REKAP (Faktur)'!$B6) -> 0 | H6: =COUNTIFS('Data (Per Faktur)'!$A:$A,'REKAP (Faktur)'!H$4,'Data (Per Faktur)'!$K:$K,'REKAP (Faktur)'!$B6) -> 0 | I6: =COUNTIFS('Data (Per Faktur)'!$A:$A,'REKAP (Faktur)'!I$4,'Data (Per Faktur)'!$K:$K,'REKAP (Faktur)'!$B6) -> 0 | J6: =COUNTIFS('Data (Per Faktur)'!$A:$A,'REKAP (Faktur)'!J$4,'Data (Per Faktur)'!$K:$K,'REKAP (Faktur)'!$B6) -> 0 | ... N6: =COUNTIFS('Data (Per Faktur)'!$A:$A,'REKAP (Faktur)'!N$4,'Data (Per Faktur)'!$K:$K,'REKAP (Faktur)'!$B6) -> 0 | O6: =SUM(C6:N6) -> 1 | Q6: 10 | R6: =+O6-Q6 -> -9
B7: Pembatalan Order Oleh Kios | C7: =COUNTIFS('Data (Per Faktur)'!$A:$A,'REKAP (Faktur)'!C$4,'Data (Per Faktur)'!$K:$K,'REKAP (Faktur)'!$B7) -> 2 | D7: =COUNTIFS('Data (Per Faktur)'!$A:$A,'REKAP (Faktur)'!D$4,'Data (Per Faktur)'!$K:$K,'REKAP (Faktur)'!$B7) -> 3 | E7: =COUNTIFS('Data (Per Faktur)'!$A:$A,'REKAP (Faktur)'!E$4,'Data (Per Faktur)'!$K:$K,'REKAP (Faktur)'!$B7) -> 0 | F7: =COUNTIFS('Data (Per Faktur)'!$A:$A,'REKAP (Faktur)'!F$4,'Data (Per Faktur)'!$K:$K,'REKAP (Faktur)'!$B7) -> 2 | G7: =COUNTIFS('Data (Per Faktur)'!$A:$A,'REKAP (Faktur)'!G$4,'Data (Per Faktur)'!$K:$K,'REKAP (Faktur)'!$B7) -> 3 | H7: =COUNTIFS('Data (Per Faktur)'!$A:$A,'REKAP (Faktur)'!H$4,'Data (Per Faktur)'!$K:$K,'REKAP (Faktur)'!$B7) -> 0 | I7: =COUNTIFS('Data (Per Faktur)'!$A:$A,'REKAP (Faktur)'!I$4,'Data (Per Faktur)'!$K:$K,'REKAP (Faktur)'!$B7) -> 0 | J7: =COUNTIFS('Data (Per Faktur)'!$A:$A,'REKAP (Faktur)'!J$4,'Data (Per Faktur)'!$K:$K,'REKAP (Faktur)'!$B7) -> 0 | ... N7: =COUNTIFS('Data (Per Faktur)'!$A:$A,'REKAP (Faktur)'!N$4,'Data (Per Faktur)'!$K:$K,'REKAP (Faktur)'!$B7) -> 0 | O7: =SUM(C7:N7) -> 10 | Q7: 4 | R7: =+O7-Q7 -> 6
B8: Retur | C8: =COUNTIFS('Data (Per Faktur)'!$A:$A,'REKAP (Faktur)'!C$4,'Data (Per Faktur)'!$K:$K,'REKAP (Faktur)'!$B8) -> 6 | D8: =COUNTIFS('Data (Per Faktur)'!$A:$A,'REKAP (Faktur)'!D$4,'Data (Per Faktur)'!$K:$K,'REKAP (Faktur)'!$B8) -> 4 | E8: =COUNTIFS('Data (Per Faktur)'!$A:$A,'REKAP (Faktur)'!E$4,'Data (Per Faktur)'!$K:$K,'REKAP (Faktur)'!$B8) -> 3 | F8: =COUNTIFS('Data (Per Faktur)'!$A:$A,'REKAP (Faktur)'!F$4,'Data (Per Faktur)'!$K:$K,'REKAP (Faktur)'!$B8) -> 5 | G8: =COUNTIFS('Data (Per Faktur)'!$A:$A,'REKAP (Faktur)'!G$4,'Data (Per Faktur)'!$K:$K,'REKAP (Faktur)'!$B8) -> 7 | H8: =COUNTIFS('Data (Per Faktur)'!$A:$A,'REKAP (Faktur)'!H$4,'Data (Per Faktur)'!$K:$K,'REKAP (Faktur)'!$B8) -> 0 | I8: =COUNTIFS('Data (Per Faktur)'!$A:$A,'REKAP (Faktur)'!I$4,'Data (Per Faktur)'!$K:$K,'REKAP (Faktur)'!$B8) -> 0 | J8: =COUNTIFS('Data (Per Faktur)'!$A:$A,'REKAP (Faktur)'!J$4,'Data (Per Faktur)'!$K:$K,'REKAP (Faktur)'!$B8) -> 0 | ... N8: =COUNTIFS('Data (Per Faktur)'!$A:$A,'REKAP (Faktur)'!N$4,'Data (Per Faktur)'!$K:$K,'REKAP (Faktur)'!$B8) -> 0 | O8: =SUM(C8:N8) -> 25 | Q8: 16 | R8: =+O8-Q8 -> 9
B9: Kios Batal TRF/ Tidak Tepat Janji | C9: =COUNTIFS('Data (Per Faktur)'!$A:$A,'REKAP (Faktur)'!C$4,'Data (Per Faktur)'!$K:$K,'REKAP (Faktur)'!$B9) -> 2 | D9: =COUNTIFS('Data (Per Faktur)'!$A:$A,'REKAP (Faktur)'!D$4,'Data (Per Faktur)'!$K:$K,'REKAP (Faktur)'!$B9) -> 1 | E9: =COUNTIFS('Data (Per Faktur)'!$A:$A,'REKAP (Faktur)'!E$4,'Data (Per Faktur)'!$K:$K,'REKAP (Faktur)'!$B9) -> 0 | F9: =COUNTIFS('Data (Per Faktur)'!$A:$A,'REKAP (Faktur)'!F$4,'Data (Per Faktur)'!$K:$K,'REKAP (Faktur)'!$B9) -> 1 | G9: =COUNTIFS('Data (Per Faktur)'!$A:$A,'REKAP (Faktur)'!G$4,'Data (Per Faktur)'!$K:$K,'REKAP (Faktur)'!$B9) -> 1 | H9: =COUNTIFS('Data (Per Faktur)'!$A:$A,'REKAP (Faktur)'!H$4,'Data (Per Faktur)'!$K:$K,'REKAP (Faktur)'!$B9) -> 0 | I9: =COUNTIFS('Data (Per Faktur)'!$A:$A,'REKAP (Faktur)'!I$4,'Data (Per Faktur)'!$K:$K,'REKAP (Faktur)'!$B9) -> 0 | J9: =COUNTIFS('Data (Per Faktur)'!$A:$A,'REKAP (Faktur)'!J$4,'Data (Per Faktur)'!$K:$K,'REKAP (Faktur)'!$B9) -> 0 | ... N9: =COUNTIFS('Data (Per Faktur)'!$A:$A,'REKAP (Faktur)'!N$4,'Data (Per Faktur)'!$K:$K,'REKAP (Faktur)'!$B9) -> 0 | O9: =SUM(C9:N9) -> 5 | Q9: 0 | R9: =+O9-Q9 -> 5
B10: Salah Input Oleh Admin SC | C10: =COUNTIFS('Data (Per Faktur)'!$A:$A,'REKAP (Faktur)'!C$4,'Data (Per Faktur)'!$K:$K,'REKAP (Faktur)'!$B10) -> 0 | D10: =COUNTIFS('Data (Per Faktur)'!$A:$A,'REKAP (Faktur)'!D$4,'Data (Per Faktur)'!$K:$K,'REKAP (Faktur)'!$B10) -> 0 | E10: =COUNTIFS('Data (Per Faktur)'!$A:$A,'REKAP (Faktur)'!E$4,'Data (Per Faktur)'!$K:$K,'REKAP (Faktur)'!$B10) -> 4 | F10: =COUNTIFS('Data (Per Faktur)'!$A:$A,'REKAP (Faktur)'!F$4,'Data (Per Faktur)'!$K:$K,'REKAP (Faktur)'!$B10) -> 1 | G10: =COUNTIFS('Data (Per Faktur)'!$A:$A,'REKAP (Faktur)'!G$4,'Data (Per Faktur)'!$K:$K,'REKAP (Faktur)'!$B10) -> 0 | H10: =COUNTIFS('Data (Per Faktur)'!$A:$A,'REKAP (Faktur)'!H$4,'Data (Per Faktur)'!$K:$K,'REKAP (Faktur)'!$B10) -> 0 | I10: =COUNTIFS('Data (Per Faktur)'!$A:$A,'REKAP (Faktur)'!I$4,'Data (Per Faktur)'!$K:$K,'REKAP (Faktur)'!$B10) -> 0 | J10: =COUNTIFS('Data (Per Faktur)'!$A:$A,'REKAP (Faktur)'!J$4,'Data (Per Faktur)'!$K:$K,'REKAP (Faktur)'!$B10) -> 0 | ... N10: =COUNTIFS('Data (Per Faktur)'!$A:$A,'REKAP (Faktur)'!N$4,'Data (Per Faktur)'!$K:$K,'REKAP (Faktur)'!$B10) -> 0 | O10: =SUM(C10:N10) -> 5 | Q10: 9 | R10: =+O10-Q10 -> -4
B11: Salah harga Oleh SC | C11: =COUNTIFS('Data (Per Faktur)'!$A:$A,'REKAP (Faktur)'!C$4,'Data (Per Faktur)'!$K:$K,'REKAP (Faktur)'!$B11) -> 1 | D11: =COUNTIFS('Data (Per Faktur)'!$A:$A,'REKAP (Faktur)'!D$4,'Data (Per Faktur)'!$K:$K,'REKAP (Faktur)'!$B11) -> 0 | E11: =COUNTIFS('Data (Per Faktur)'!$A:$A,'REKAP (Faktur)'!E$4,'Data (Per Faktur)'!$K:$K,'REKAP (Faktur)'!$B11) -> 0 | F11: =COUNTIFS('Data (Per Faktur)'!$A:$A,'REKAP (Faktur)'!F$4,'Data (Per Faktur)'!$K:$K,'REKAP (Faktur)'!$B11) -> 1 | G11: =COUNTIFS('Data (Per Faktur)'!$A:$A,'REKAP (Faktur)'!G$4,'Data (Per Faktur)'!$K:$K,'REKAP (Faktur)'!$B11) -> 0 | H11: =COUNTIFS('Data (Per Faktur)'!$A:$A,'REKAP (Faktur)'!H$4,'Data (Per Faktur)'!$K:$K,'REKAP (Faktur)'!$B11) -> 0 | I11: =COUNTIFS('Data (Per Faktur)'!$A:$A,'REKAP (Faktur)'!I$4,'Data (Per Faktur)'!$K:$K,'REKAP (Faktur)'!$B11) -> 0 | J11: =COUNTIFS('Data (Per Faktur)'!$A:$A,'REKAP (Faktur)'!J$4,'Data (Per Faktur)'!$K:$K,'REKAP (Faktur)'!$B11) -> 0 | ... N11: =COUNTIFS('Data (Per Faktur)'!$A:$A,'REKAP (Faktur)'!N$4,'Data (Per Faktur)'!$K:$K,'REKAP (Faktur)'!$B11) -> 0 | O11: =SUM(C11:N11) -> 2 | Q11: 7 | R11: =+O11-Q11 -> -5
B12: Harga tidak cocok | C12: =COUNTIFS('Data (Per Faktur)'!$A:$A,'REKAP (Faktur)'!C$4,'Data (Per Faktur)'!$K:$K,'REKAP (Faktur)'!$B12) -> 0 | D12: =COUNTIFS('Data (Per Faktur)'!$A:$A,'REKAP (Faktur)'!D$4,'Data (Per Faktur)'!$K:$K,'REKAP (Faktur)'!$B12) -> 0 | E12: =COUNTIFS('Data (Per Faktur)'!$A:$A,'REKAP (Faktur)'!E$4,'Data (Per Faktur)'!$K:$K,'REKAP (Faktur)'!$B12) -> 0 | F12: =COUNTIFS('Data (Per Faktur)'!$A:$A,'REKAP (Faktur)'!F$4,'Data (Per Faktur)'!$K:$K,'REKAP (Faktur)'!$B12) -> 0 | G12: =COUNTIFS('Data (Per Faktur)'!$A:$A,'REKAP (Faktur)'!G$4,'Data (Per Faktur)'!$K:$K,'REKAP (Faktur)'!$B12) -> 0 | H12: =COUNTIFS('Data (Per Faktur)'!$A:$A,'REKAP (Faktur)'!H$4,'Data (Per Faktur)'!$K:$K,'REKAP (Faktur)'!$B12) -> 0 | I12: =COUNTIFS('Data (Per Faktur)'!$A:$A,'REKAP (Faktur)'!I$4,'Data (Per Faktur)'!$K:$K,'REKAP (Faktur)'!$B12) -> 0 | J12: =COUNTIFS('Data (Per Faktur)'!$A:$A,'REKAP (Faktur)'!J$4,'Data (Per Faktur)'!$K:$K,'REKAP (Faktur)'!$B12) -> 0 | ... N12: =COUNTIFS('Data (Per Faktur)'!$A:$A,'REKAP (Faktur)'!N$4,'Data (Per Faktur)'!$K:$K,'REKAP (Faktur)'!$B12) -> 0 | O12: =SUM(C12:N12) -> 0 | Q12: 0 | R12: =+O12-Q12 -> 0
B13: Salah SO oleh SC | C13: =COUNTIFS('Data (Per Faktur)'!$A:$A,'REKAP (Faktur)'!C$4,'Data (Per Faktur)'!$K:$K,'REKAP (Faktur)'!$B13) -> 2 | D13: =COUNTIFS('Data (Per Faktur)'!$A:$A,'REKAP (Faktur)'!D$4,'Data (Per Faktur)'!$K:$K,'REKAP (Faktur)'!$B13) -> 0 | E13: =COUNTIFS('Data (Per Faktur)'!$A:$A,'REKAP (Faktur)'!E$4,'Data (Per Faktur)'!$K:$K,'REKAP (Faktur)'!$B13) -> 0 | F13: =COUNTIFS('Data (Per Faktur)'!$A:$A,'REKAP (Faktur)'!F$4,'Data (Per Faktur)'!$K:$K,'REKAP (Faktur)'!$B13) -> 0 | G13: =COUNTIFS('Data (Per Faktur)'!$A:$A,'REKAP (Faktur)'!G$4,'Data (Per Faktur)'!$K:$K,'REKAP (Faktur)'!$B13) -> 0 | H13: =COUNTIFS('Data (Per Faktur)'!$A:$A,'REKAP (Faktur)'!H$4,'Data (Per Faktur)'!$K:$K,'REKAP (Faktur)'!$B13) -> 0 | I13: =COUNTIFS('Data (Per Faktur)'!$A:$A,'REKAP (Faktur)'!I$4,'Data (Per Faktur)'!$K:$K,'REKAP (Faktur)'!$B13) -> 0 | J13: =COUNTIFS('Data (Per Faktur)'!$A:$A,'REKAP (Faktur)'!J$4,'Data (Per Faktur)'!$K:$K,'REKAP (Faktur)'!$B13) -> 0 | ... N13: =COUNTIFS('Data (Per Faktur)'!$A:$A,'REKAP (Faktur)'!N$4,'Data (Per Faktur)'!$K:$K,'REKAP (Faktur)'!$B13) -> 0 | O13: =SUM(C13:N13) -> 2 | Q13: 9 | R13: =+O13-Q13 -> -7
B14: Pembagian Barang ke kios Lain | C14: =COUNTIFS('Data (Per Faktur)'!$A:$A,'REKAP (Faktur)'!C$4,'Data (Per Faktur)'!$K:$K,'REKAP (Faktur)'!$B14) -> 0 | D14: =COUNTIFS('Data (Per Faktur)'!$A:$A,'REKAP (Faktur)'!D$4,'Data (Per Faktur)'!$K:$K,'REKAP (Faktur)'!$B14) -> 0 | E14: =COUNTIFS('Data (Per Faktur)'!$A:$A,'REKAP (Faktur)'!E$4,'Data (Per Faktur)'!$K:$K,'REKAP (Faktur)'!$B14) -> 0 | F14: =COUNTIFS('Data (Per Faktur)'!$A:$A,'REKAP (Faktur)'!F$4,'Data (Per Faktur)'!$K:$K,'REKAP (Faktur)'!$B14) -> 1 | G14: =COUNTIFS('Data (Per Faktur)'!$A:$A,'REKAP (Faktur)'!G$4,'Data (Per Faktur)'!$K:$K,'REKAP (Faktur)'!$B14) -> 0 | H14: =COUNTIFS('Data (Per Faktur)'!$A:$A,'REKAP (Faktur)'!H$4,'Data (Per Faktur)'!$K:$K,'REKAP (Faktur)'!$B14) -> 0 | I14: =COUNTIFS('Data (Per Faktur)'!$A:$A,'REKAP (Faktur)'!I$4,'Data (Per Faktur)'!$K:$K,'REKAP (Faktur)'!$B14) -> 0 | J14: =COUNTIFS('Data (Per Faktur)'!$A:$A,'REKAP (Faktur)'!J$4,'Data (Per Faktur)'!$K:$K,'REKAP (Faktur)'!$B14) -> 0 | ... N14: =COUNTIFS('Data (Per Faktur)'!$A:$A,'REKAP (Faktur)'!N$4,'Data (Per Faktur)'!$K:$K,'REKAP (Faktur)'!$B14) -> 0 | O14: =SUM(C14:N14) -> 1 | Q14: 1 | R14: =+O14-Q14 -> 0
B15: Barang Rusak/Cacat/Bocor/Exp | C15: =COUNTIFS('Data (Per Faktur)'!$A:$A,'REKAP (Faktur)'!C$4,'Data (Per Faktur)'!$K:$K,'REKAP (Faktur)'!$B15) -> 0 | D15: =COUNTIFS('Data (Per Faktur)'!$A:$A,'REKAP (Faktur)'!D$4,'Data (Per Faktur)'!$K:$K,'REKAP (Faktur)'!$B15) -> 0 | E15: =COUNTIFS('Data (Per Faktur)'!$A:$A,'REKAP (Faktur)'!E$4,'Data (Per Faktur)'!$K:$K,'REKAP (Faktur)'!$B15) -> 0 | F15: =COUNTIFS('Data (Per Faktur)'!$A:$A,'REKAP (Faktur)'!F$4,'Data (Per Faktur)'!$K:$K,'REKAP (Faktur)'!$B15) -> 0 | G15: =COUNTIFS('Data (Per Faktur)'!$A:$A,'REKAP (Faktur)'!G$4,'Data (Per Faktur)'!$K:$K,'REKAP (Faktur)'!$B15) -> 0 | H15: =COUNTIFS('Data (Per Faktur)'!$A:$A,'REKAP (Faktur)'!H$4,'Data (Per Faktur)'!$K:$K,'REKAP (Faktur)'!$B15) -> 0 | I15: =COUNTIFS('Data (Per Faktur)'!$A:$A,'REKAP (Faktur)'!I$4,'Data (Per Faktur)'!$K:$K,'REKAP (Faktur)'!$B15) -> 0 | J15: =COUNTIFS('Data (Per Faktur)'!$A:$A,'REKAP (Faktur)'!J$4,'Data (Per Faktur)'!$K:$K,'REKAP (Faktur)'!$B15) -> 0 | ... N15: =COUNTIFS('Data (Per Faktur)'!$A:$A,'REKAP (Faktur)'!N$4,'Data (Per Faktur)'!$K:$K,'REKAP (Faktur)'!$B15) -> 0 | O15: =SUM(C15:N15) -> 0 | Q15: 1 | R15: =+O15-Q15 -> -1
B16: Toko Double Order | C16: =COUNTIFS('Data (Per Faktur)'!$A:$A,'REKAP (Faktur)'!C$4,'Data (Per Faktur)'!$K:$K,'REKAP (Faktur)'!$B16) -> 0 | D16: =COUNTIFS('Data (Per Faktur)'!$A:$A,'REKAP (Faktur)'!D$4,'Data (Per Faktur)'!$K:$K,'REKAP (Faktur)'!$B16) -> 0 | E16: =COUNTIFS('Data (Per Faktur)'!$A:$A,'REKAP (Faktur)'!E$4,'Data (Per Faktur)'!$K:$K,'REKAP (Faktur)'!$B16) -> 0 | F16: =COUNTIFS('Data (Per Faktur)'!$A:$A,'REKAP (Faktur)'!F$4,'Data (Per Faktur)'!$K:$K,'REKAP (Faktur)'!$B16) -> 0 | G16: =COUNTIFS('Data (Per Faktur)'!$A:$A,'REKAP (Faktur)'!G$4,'Data (Per Faktur)'!$K:$K,'REKAP (Faktur)'!$B16) -> 0 | H16: =COUNTIFS('Data (Per Faktur)'!$A:$A,'REKAP (Faktur)'!H$4,'Data (Per Faktur)'!$K:$K,'REKAP (Faktur)'!$B16) -> 0 | I16: =COUNTIFS('Data (Per Faktur)'!$A:$A,'REKAP (Faktur)'!I$4,'Data (Per Faktur)'!$K:$K,'REKAP (Faktur)'!$B16) -> 0 | J16: =COUNTIFS('Data (Per Faktur)'!$A:$A,'REKAP (Faktur)'!J$4,'Data (Per Faktur)'!$K:$K,'REKAP (Faktur)'!$B16) -> 0 | ... N16: =COUNTIFS('Data (Per Faktur)'!$A:$A,'REKAP (Faktur)'!N$4,'Data (Per Faktur)'!$K:$K,'REKAP (Faktur)'!$B16) -> 0 | O16: =SUM(C16:N16) -> 0 | Q16: 0 | R16: =+O16-Q16 -> 0
... B28: Ketinggalan Kiriman | C28: =COUNTIFS('Data (Per Faktur)'!$A:$A,'REKAP (Faktur)'!C$4,'Data (Per Faktur)'!$K:$K,'REKAP (Faktur)'!$B28) -> 0 | D28: =COUNTIFS('Data (Per Faktur)'!$A:$A,'REKAP (Faktur)'!D$4,'Data (Per Faktur)'!$K:$K,'REKAP (Faktur)'!$B28) -> 0 | E28: =COUNTIFS('Data (Per Faktur)'!$A:$A,'REKAP (Faktur)'!E$4,'Data (Per Faktur)'!$K:$K,'REKAP (Faktur)'!$B28) -> 0 | F28: =COUNTIFS('Data (Per Faktur)'!$A:$A,'REKAP (Faktur)'!F$4,'Data (Per Faktur)'!$K:$K,'REKAP (Faktur)'!$B28) -> 0 | G28: =COUNTIFS('Data (Per Faktur)'!$A:$A,'REKAP (Faktur)'!G$4,'Data (Per Faktur)'!$K:$K,'REKAP (Faktur)'!$B28) -> 0 | H28: =COUNTIFS('Data (Per Faktur)'!$A:$A,'REKAP (Faktur)'!H$4,'Data (Per Faktur)'!$K:$K,'REKAP (Faktur)'!$B28) -> 0 | I28: =COUNTIFS('Data (Per Faktur)'!$A:$A,'REKAP (Faktur)'!I$4,'Data (Per Faktur)'!$K:$K,'REKAP (Faktur)'!$B28) -> 0 | J28: =COUNTIFS('Data (Per Faktur)'!$A:$A,'REKAP (Faktur)'!J$4,'Data (Per Faktur)'!$K:$K,'REKAP (Faktur)'!$B28) -> 0 | ... N28: =COUNTIFS('Data (Per Faktur)'!$A:$A,'REKAP (Faktur)'!N$4,'Data (Per Faktur)'!$K:$K,'REKAP (Faktur)'!$B28) -> 0 | O28: =SUM(C28:N28) -> 0 | Q28: 0 | R28: =+O28-Q28 -> 0
B29: Salah Harga | C29: =COUNTIFS('Data (Per Faktur)'!$A:$A,'REKAP (Faktur)'!C$4,'Data (Per Faktur)'!$K:$K,'REKAP (Faktur)'!$B29) -> 0 | D29: =COUNTIFS('Data (Per Faktur)'!$A:$A,'REKAP (Faktur)'!D$4,'Data (Per Faktur)'!$K:$K,'REKAP (Faktur)'!$B29) -> 0 | E29: =COUNTIFS('Data (Per Faktur)'!$A:$A,'REKAP (Faktur)'!E$4,'Data (Per Faktur)'!$K:$K,'REKAP (Faktur)'!$B29) -> 0 | O29: =SUM(C29:N29) -> 0 | Q29: 0 | R29: =+O29-Q29 -> 0
B30: Grand Total | C30: =SUM(C5:C28) -> 16 | D30: =SUM(D5:D29) -> 12 | E30: =SUM(E5:E29) -> 13 | F30: =SUM(F5:F29) -> 16 | G30: =SUM(G5:G29) -> 18 | H30: =SUM(H5:H29) -> 0 | I30: =SUM(I5:I29) -> 0 | J30: =SUM(J5:J29) -> 0 | K30: =SUM(K5:K29) -> 0 | ... O30: =SUM(O5:O29) -> 75 | Q30: =SUM(Q5:Q29) -> 112 | R30: =+O30-Q30 -> -37
B31: TARGET : 200 Revisi Faktur sd Desember 2026, Per bulan maksimal 16 Revisi Faktur
A34: Salah harga Oleh SC | B34: REVISI FAKTUR BERDASARKAN SC (Salah Harga) | P34: Salah SO oleh SC | Q34: REVISI FAKTUR BERDASARKAN SC (Salah SO)
B35: Periode Januari 2025 | Q35: Periode Januari 2025
B36: SC | C36: Januari | D36: Februari | E36: Maret | F36: April | G36: Mei | H36: Juni | I36: Juli | J36: Agustus | K36: September | L36: Oktober | M36: November | N36: Desember | O36: Total | Q36: SC | R36: Januari | S36: Februari | T36: Maret | U36: April | V36: Mei | W36: Juni | X36: Juli | Y36: Agustus | Z36: September | AA36: Oktober | AB36: November | AC36: Desember | AD36: Total | AE36: %
B37: Arasyi | O37: =SUM(C37:N37) -> 0 | Q37: Arasyi | R37: =COUNTIFS('Data (Per Faktur)'!$A:$A,'REKAP (Faktur)'!R$36,'Data (Per Faktur)'!$E:$E,'REKAP (Faktur)'!$Q37,'Data (Per Faktur)'!$K:$K,'REKAP (Faktur)'!$P$34) -> 0 | S37: =COUNTIFS('Data (Per Faktur)'!$A:$A,'REKAP (Faktur)'!S$36,'Data (Per Faktur)'!$E:$E,'REKAP (Faktur)'!$Q37,'Data (Per Faktur)'!$K:$K,'REKAP (Faktur)'!$P$34) -> 0 | T37: =COUNTIFS('Data (Per Faktur)'!$A:$A,'REKAP (Faktur)'!T$36,'Data (Per Faktur)'!$E:$E,'REKAP (Faktur)'!$Q37,'Data (Per Faktur)'!$K:$K,'REKAP (Faktur)'!$P$34) -> 0 | U37: =COUNTIFS('Data (Per Faktur)'!$A:$A,'REKAP (Faktur)'!U$36,'Data (Per Faktur)'!$E:$E,'REKAP (Faktur)'!$Q37,'Data (Per Faktur)'!$K:$K,'REKAP (Faktur)'!$P$34) -> 0 | V37: =COUNTIFS('Data (Per Faktur)'!$A:$A,'REKAP (Faktur)'!V$36,'Data (Per Faktur)'!$E:$E,'REKAP (Faktur)'!$Q37,'Data (Per Faktur)'!$K:$K,'REKAP (Faktur)'!$P$34) -> 0 | W37: =COUNTIFS('Data (Per Faktur)'!$A:$A,'REKAP (Faktur)'!W$36,'Data (Per Faktur)'!$E:$E,'REKAP (Faktur)'!$Q37,'Data (Per Faktur)'!$K:$K,'REKAP (Faktur)'!$P$34) -> 0 | X37: =COUNTIFS('Data (Per Faktur)'!$A:$A,'REKAP (Faktur)'!X$36,'Data (Per Faktur)'!$E:$E,'REKAP (Faktur)'!$Q37,'Data (Per Faktur)'!$K:$K,'REKAP (Faktur)'!$P$34) -> 0 | Y37: =COUNTIFS('Data (Per Faktur)'!$A:$A,'REKAP (Faktur)'!Y$36,'Data (Per Faktur)'!$E:$E,'REKAP (Faktur)'!$Q37,'Data (Per Faktur)'!$K:$K,'REKAP (Faktur)'!$P$34) -> 0 | ... AC37: =COUNTIFS('Data (Per Faktur)'!$A:$A,'REKAP (Faktur)'!AC$36,'Data (Per Faktur)'!$E:$E,'REKAP (Faktur)'!$Q37,'Data (Per Faktur)'!$K:$K,'REKAP (Faktur)'!$P$34) -> 0 | AD37: =SUM(R37:AC37) -> 0 | AE37: =AD37/$AD$47 -> #DIV/0!
B38: Evi | O38: =SUM(C38:N38) -> 0 | Q38: Evi | R38: =COUNTIFS('Data (Per Faktur)'!$A:$A,'REKAP (Faktur)'!R$36,'Data (Per Faktur)'!$E:$E,'REKAP (Faktur)'!$Q38,'Data (Per Faktur)'!$K:$K,'REKAP (Faktur)'!$P$34) -> 0 | S38: =COUNTIFS('Data (Per Faktur)'!$A:$A,'REKAP (Faktur)'!S$36,'Data (Per Faktur)'!$E:$E,'REKAP (Faktur)'!$Q38,'Data (Per Faktur)'!$K:$K,'REKAP (Faktur)'!$P$34) -> 0 | T38: =COUNTIFS('Data (Per Faktur)'!$A:$A,'REKAP (Faktur)'!T$36,'Data (Per Faktur)'!$E:$E,'REKAP (Faktur)'!$Q38,'Data (Per Faktur)'!$K:$K,'REKAP (Faktur)'!$P$34) -> 0 | U38: =COUNTIFS('Data (Per Faktur)'!$A:$A,'REKAP (Faktur)'!U$36,'Data (Per Faktur)'!$E:$E,'REKAP (Faktur)'!$Q38,'Data (Per Faktur)'!$K:$K,'REKAP (Faktur)'!$P$34) -> 0 | V38: =COUNTIFS('Data (Per Faktur)'!$A:$A,'REKAP (Faktur)'!V$36,'Data (Per Faktur)'!$E:$E,'REKAP (Faktur)'!$Q38,'Data (Per Faktur)'!$K:$K,'REKAP (Faktur)'!$P$34) -> 0 | W38: =COUNTIFS('Data (Per Faktur)'!$A:$A,'REKAP (Faktur)'!W$36,'Data (Per Faktur)'!$E:$E,'REKAP (Faktur)'!$Q38,'Data (Per Faktur)'!$K:$K,'REKAP (Faktur)'!$P$34) -> 0 | X38: =COUNTIFS('Data (Per Faktur)'!$A:$A,'REKAP (Faktur)'!X$36,'Data (Per Faktur)'!$E:$E,'REKAP (Faktur)'!$Q38,'Data (Per Faktur)'!$K:$K,'REKAP (Faktur)'!$P$34) -> 0 | Y38: =COUNTIFS('Data (Per Faktur)'!$A:$A,'REKAP (Faktur)'!Y$36,'Data (Per Faktur)'!$E:$E,'REKAP (Faktur)'!$Q38,'Data (Per Faktur)'!$K:$K,'REKAP (Faktur)'!$P$34) -> 0 | ... AC38: =COUNTIFS('Data (Per Faktur)'!$A:$A,'REKAP (Faktur)'!AC$36,'Data (Per Faktur)'!$E:$E,'REKAP (Faktur)'!$Q38,'Data (Per Faktur)'!$K:$K,'REKAP (Faktur)'!$P$34) -> 0 | AD38: =SUM(R38:AC38) -> 0 | AE38: =AD38/$AD$47 -> #DIV/0!
B39: Faisal | O39: =SUM(C39:N39) -> 0 | Q39: Faisal | R39: =COUNTIFS('Data (Per Faktur)'!$A:$A,'REKAP (Faktur)'!R$36,'Data (Per Faktur)'!$E:$E,'REKAP (Faktur)'!$Q39,'Data (Per Faktur)'!$K:$K,'REKAP (Faktur)'!$P$34) -> 0 | S39: =COUNTIFS('Data (Per Faktur)'!$A:$A,'REKAP (Faktur)'!S$36,'Data (Per Faktur)'!$E:$E,'REKAP (Faktur)'!$Q39,'Data (Per Faktur)'!$K:$K,'REKAP (Faktur)'!$P$34) -> 0 | T39: =COUNTIFS('Data (Per Faktur)'!$A:$A,'REKAP (Faktur)'!T$36,'Data (Per Faktur)'!$E:$E,'REKAP (Faktur)'!$Q39,'Data (Per Faktur)'!$K:$K,'REKAP (Faktur)'!$P$34) -> 0 | U39: =COUNTIFS('Data (Per Faktur)'!$A:$A,'REKAP (Faktur)'!U$36,'Data (Per Faktur)'!$E:$E,'REKAP (Faktur)'!$Q39,'Data (Per Faktur)'!$K:$K,'REKAP (Faktur)'!$P$34) -> 0 | V39: =COUNTIFS('Data (Per Faktur)'!$A:$A,'REKAP (Faktur)'!V$36,'Data (Per Faktur)'!$E:$E,'REKAP (Faktur)'!$Q39,'Data (Per Faktur)'!$K:$K,'REKAP (Faktur)'!$P$34) -> 0 | W39: =COUNTIFS('Data (Per Faktur)'!$A:$A,'REKAP (Faktur)'!W$36,'Data (Per Faktur)'!$E:$E,'REKAP (Faktur)'!$Q39,'Data (Per Faktur)'!$K:$K,'REKAP (Faktur)'!$P$34) -> 0 | X39: =COUNTIFS('Data (Per Faktur)'!$A:$A,'REKAP (Faktur)'!X$36,'Data (Per Faktur)'!$E:$E,'REKAP (Faktur)'!$Q39,'Data (Per Faktur)'!$K:$K,'REKAP (Faktur)'!$P$34) -> 0 | Y39: =COUNTIFS('Data (Per Faktur)'!$A:$A,'REKAP (Faktur)'!Y$36,'Data (Per Faktur)'!$E:$E,'REKAP (Faktur)'!$Q39,'Data (Per Faktur)'!$K:$K,'REKAP (Faktur)'!$P$34) -> 0 | ... AC39: =COUNTIFS('Data (Per Faktur)'!$A:$A,'REKAP (Faktur)'!AC$36,'Data (Per Faktur)'!$E:$E,'REKAP (Faktur)'!$Q39,'Data (Per Faktur)'!$K:$K,'REKAP (Faktur)'!$P$34) -> 0 | AD39: =SUM(R39:AC39) -> 0 | AE39: =AD39/$AD$47 -> #DIV/0!
B40: Faris | O40: =SUM(C40:N40) -> 0 | Q40: Faris | R40: =COUNTIFS('Data (Per Faktur)'!$A:$A,'REKAP (Faktur)'!R$36,'Data (Per Faktur)'!$E:$E,'REKAP (Faktur)'!$Q40,'Data (Per Faktur)'!$K:$K,'REKAP (Faktur)'!$P$34) -> 0 | S40: =COUNTIFS('Data (Per Faktur)'!$A:$A,'REKAP (Faktur)'!S$36,'Data (Per Faktur)'!$E:$E,'REKAP (Faktur)'!$Q40,'Data (Per Faktur)'!$K:$K,'REKAP (Faktur)'!$P$34) -> 0 | T40: =COUNTIFS('Data (Per Faktur)'!$A:$A,'REKAP (Faktur)'!T$36,'Data (Per Faktur)'!$E:$E,'REKAP (Faktur)'!$Q40,'Data (Per Faktur)'!$K:$K,'REKAP (Faktur)'!$P$34) -> 0 | U40: =COUNTIFS('Data (Per Faktur)'!$A:$A,'REKAP (Faktur)'!U$36,'Data (Per Faktur)'!$E:$E,'REKAP (Faktur)'!$Q40,'Data (Per Faktur)'!$K:$K,'REKAP (Faktur)'!$P$34) -> 0 | V40: =COUNTIFS('Data (Per Faktur)'!$A:$A,'REKAP (Faktur)'!V$36,'Data (Per Faktur)'!$E:$E,'REKAP (Faktur)'!$Q40,'Data (Per Faktur)'!$K:$K,'REKAP (Faktur)'!$P$34) -> 0 | W40: =COUNTIFS('Data (Per Faktur)'!$A:$A,'REKAP (Faktur)'!W$36,'Data (Per Faktur)'!$E:$E,'REKAP (Faktur)'!$Q40,'Data (Per Faktur)'!$K:$K,'REKAP (Faktur)'!$P$34) -> 0 | X40: =COUNTIFS('Data (Per Faktur)'!$A:$A,'REKAP (Faktur)'!X$36,'Data (Per Faktur)'!$E:$E,'REKAP (Faktur)'!$Q40,'Data (Per Faktur)'!$K:$K,'REKAP (Faktur)'!$P$34) -> 0 | Y40: =COUNTIFS('Data (Per Faktur)'!$A:$A,'REKAP (Faktur)'!Y$36,'Data (Per Faktur)'!$E:$E,'REKAP (Faktur)'!$Q40,'Data (Per Faktur)'!$K:$K,'REKAP (Faktur)'!$P$34) -> 0 | ... AC40: =COUNTIFS('Data (Per Faktur)'!$A:$A,'REKAP (Faktur)'!AC$36,'Data (Per Faktur)'!$E:$E,'REKAP (Faktur)'!$Q40,'Data (Per Faktur)'!$K:$K,'REKAP (Faktur)'!$P$34) -> 0 | AD40: =SUM(R40:AC40) -> 0
B41: Hendra | O41: =SUM(C41:N41) -> 0 | Q41: Hendra | R41: =COUNTIFS('Data (Per Faktur)'!$A:$A,'REKAP (Faktur)'!R$36,'Data (Per Faktur)'!$E:$E,'REKAP (Faktur)'!$Q41,'Data (Per Faktur)'!$K:$K,'REKAP (Faktur)'!$P$34) -> 0 | S41: =COUNTIFS('Data (Per Faktur)'!$A:$A,'REKAP (Faktur)'!S$36,'Data (Per Faktur)'!$E:$E,'REKAP (Faktur)'!$Q41,'Data (Per Faktur)'!$K:$K,'REKAP (Faktur)'!$P$34) -> 0 | T41: =COUNTIFS('Data (Per Faktur)'!$A:$A,'REKAP (Faktur)'!T$36,'Data (Per Faktur)'!$E:$E,'REKAP (Faktur)'!$Q41,'Data (Per Faktur)'!$K:$K,'REKAP (Faktur)'!$P$34) -> 0 | U41: =COUNTIFS('Data (Per Faktur)'!$A:$A,'REKAP (Faktur)'!U$36,'Data (Per Faktur)'!$E:$E,'REKAP (Faktur)'!$Q41,'Data (Per Faktur)'!$K:$K,'REKAP (Faktur)'!$P$34) -> 0 | V41: =COUNTIFS('Data (Per Faktur)'!$A:$A,'REKAP (Faktur)'!V$36,'Data (Per Faktur)'!$E:$E,'REKAP (Faktur)'!$Q41,'Data (Per Faktur)'!$K:$K,'REKAP (Faktur)'!$P$34) -> 0 | W41: =COUNTIFS('Data (Per Faktur)'!$A:$A,'REKAP (Faktur)'!W$36,'Data (Per Faktur)'!$E:$E,'REKAP (Faktur)'!$Q41,'Data (Per Faktur)'!$K:$K,'REKAP (Faktur)'!$P$34) -> 0 | X41: =COUNTIFS('Data (Per Faktur)'!$A:$A,'REKAP (Faktur)'!X$36,'Data (Per Faktur)'!$E:$E,'REKAP (Faktur)'!$Q41,'Data (Per Faktur)'!$K:$K,'REKAP (Faktur)'!$P$34) -> 0 | Y41: =COUNTIFS('Data (Per Faktur)'!$A:$A,'REKAP (Faktur)'!Y$36,'Data (Per Faktur)'!$E:$E,'REKAP (Faktur)'!$Q41,'Data (Per Faktur)'!$K:$K,'REKAP (Faktur)'!$P$34) -> 0 | ... AC41: =COUNTIFS('Data (Per Faktur)'!$A:$A,'REKAP (Faktur)'!AC$36,'Data (Per Faktur)'!$E:$E,'REKAP (Faktur)'!$Q41,'Data (Per Faktur)'!$K:$K,'REKAP (Faktur)'!$P$34) -> 0 | AD41: =SUM(R41:AC41) -> 0
B42: Reni | O42: =SUM(C42:N42) -> 0 | Q42: Reni | AD42: =SUM(R42:AC42) -> 0
B43: Riyan | O43: =SUM(C43:N43) -> 0 | Q43: Riyan | R43: =COUNTIFS('Data (Per Faktur)'!$A:$A,'REKAP (Faktur)'!R$36,'Data (Per Faktur)'!$E:$E,'REKAP (Faktur)'!$Q43,'Data (Per Faktur)'!$K:$K,'REKAP (Faktur)'!$P$34) -> 0 | S43: =COUNTIFS('Data (Per Faktur)'!$A:$A,'REKAP (Faktur)'!S$36,'Data (Per Faktur)'!$E:$E,'REKAP (Faktur)'!$Q43,'Data (Per Faktur)'!$K:$K,'REKAP (Faktur)'!$P$34) -> 0 | T43: =COUNTIFS('Data (Per Faktur)'!$A:$A,'REKAP (Faktur)'!T$36,'Data (Per Faktur)'!$E:$E,'REKAP (Faktur)'!$Q43,'Data (Per Faktur)'!$K:$K,'REKAP (Faktur)'!$P$34) -> 0 | U43: =COUNTIFS('Data (Per Faktur)'!$A:$A,'REKAP (Faktur)'!U$36,'Data (Per Faktur)'!$E:$E,'REKAP (Faktur)'!$Q43,'Data (Per Faktur)'!$K:$K,'REKAP (Faktur)'!$P$34) -> 0 | V43: =COUNTIFS('Data (Per Faktur)'!$A:$A,'REKAP (Faktur)'!V$36,'Data (Per Faktur)'!$E:$E,'REKAP (Faktur)'!$Q43,'Data (Per Faktur)'!$K:$K,'REKAP (Faktur)'!$P$34) -> 0 | W43: =COUNTIFS('Data (Per Faktur)'!$A:$A,'REKAP (Faktur)'!W$36,'Data (Per Faktur)'!$E:$E,'REKAP (Faktur)'!$Q43,'Data (Per Faktur)'!$K:$K,'REKAP (Faktur)'!$P$34) -> 0 | X43: =COUNTIFS('Data (Per Faktur)'!$A:$A,'REKAP (Faktur)'!X$36,'Data (Per Faktur)'!$E:$E,'REKAP (Faktur)'!$Q43,'Data (Per Faktur)'!$K:$K,'REKAP (Faktur)'!$P$34) -> 0 | Y43: =COUNTIFS('Data (Per Faktur)'!$A:$A,'REKAP (Faktur)'!Y$36,'Data (Per Faktur)'!$E:$E,'REKAP (Faktur)'!$Q43,'Data (Per Faktur)'!$K:$K,'REKAP (Faktur)'!$P$34) -> 0 | ... AC43: =COUNTIFS('Data (Per Faktur)'!$A:$A,'REKAP (Faktur)'!AC$36,'Data (Per Faktur)'!$E:$E,'REKAP (Faktur)'!$Q43,'Data (Per Faktur)'!$K:$K,'REKAP (Faktur)'!$P$34) -> 0 | AD43: =SUM(R43:AC43) -> 0 | AE43: =AD43/$AD$47 -> #DIV/0!
B44: Umi | O44: =SUM(C44:N44) -> 0 | Q44: Umi | R44: =COUNTIFS('Data (Per Faktur)'!$A:$A,'REKAP (Faktur)'!R$36,'Data (Per Faktur)'!$E:$E,'REKAP (Faktur)'!$Q44,'Data (Per Faktur)'!$K:$K,'REKAP (Faktur)'!$P$34) -> 0 | S44: =COUNTIFS('Data (Per Faktur)'!$A:$A,'REKAP (Faktur)'!S$36,'Data (Per Faktur)'!$E:$E,'REKAP (Faktur)'!$Q44,'Data (Per Faktur)'!$K:$K,'REKAP (Faktur)'!$P$34) -> 0 | T44: =COUNTIFS('Data (Per Faktur)'!$A:$A,'REKAP (Faktur)'!T$36,'Data (Per Faktur)'!$E:$E,'REKAP (Faktur)'!$Q44,'Data (Per Faktur)'!$K:$K,'REKAP (Faktur)'!$P$34) -> 0 | U44: =COUNTIFS('Data (Per Faktur)'!$A:$A,'REKAP (Faktur)'!U$36,'Data (Per Faktur)'!$E:$E,'REKAP (Faktur)'!$Q44,'Data (Per Faktur)'!$K:$K,'REKAP (Faktur)'!$P$34) -> 0 | V44: =COUNTIFS('Data (Per Faktur)'!$A:$A,'REKAP (Faktur)'!V$36,'Data (Per Faktur)'!$E:$E,'REKAP (Faktur)'!$Q44,'Data (Per Faktur)'!$K:$K,'REKAP (Faktur)'!$P$34) -> 0 | W44: =COUNTIFS('Data (Per Faktur)'!$A:$A,'REKAP (Faktur)'!W$36,'Data (Per Faktur)'!$E:$E,'REKAP (Faktur)'!$Q44,'Data (Per Faktur)'!$K:$K,'REKAP (Faktur)'!$P$34) -> 0 | X44: =COUNTIFS('Data (Per Faktur)'!$A:$A,'REKAP (Faktur)'!X$36,'Data (Per Faktur)'!$E:$E,'REKAP (Faktur)'!$Q44,'Data (Per Faktur)'!$K:$K,'REKAP (Faktur)'!$P$34) -> 0 | Y44: =COUNTIFS('Data (Per Faktur)'!$A:$A,'REKAP (Faktur)'!Y$36,'Data (Per Faktur)'!$E:$E,'REKAP (Faktur)'!$Q44,'Data (Per Faktur)'!$K:$K,'REKAP (Faktur)'!$P$34) -> 0 | ... AC44: =COUNTIFS('Data (Per Faktur)'!$A:$A,'REKAP (Faktur)'!AC$36,'Data (Per Faktur)'!$E:$E,'REKAP (Faktur)'!$Q44,'Data (Per Faktur)'!$K:$K,'REKAP (Faktur)'!$P$34) -> 0 | AD44: =SUM(R44:AC44) -> 0 | AE44: =AD44/$AD$47 -> #DIV/0!
B45: Yuyun | O45: =SUM(C45:N45) -> 0 | Q45: Yuyun | R45: =COUNTIFS('Data (Per Faktur)'!$A:$A,'REKAP (Faktur)'!R$36,'Data (Per Faktur)'!$E:$E,'REKAP (Faktur)'!$Q45,'Data (Per Faktur)'!$K:$K,'REKAP (Faktur)'!$P$34) -> 0 | S45: =COUNTIFS('Data (Per Faktur)'!$A:$A,'REKAP (Faktur)'!S$36,'Data (Per Faktur)'!$E:$E,'REKAP (Faktur)'!$Q45,'Data (Per Faktur)'!$K:$K,'REKAP (Faktur)'!$P$34) -> 0 | T45: =COUNTIFS('Data (Per Faktur)'!$A:$A,'REKAP (Faktur)'!T$36,'Data (Per Faktur)'!$E:$E,'REKAP (Faktur)'!$Q45,'Data (Per Faktur)'!$K:$K,'REKAP (Faktur)'!$P$34) -> 0 | U45: =COUNTIFS('Data (Per Faktur)'!$A:$A,'REKAP (Faktur)'!U$36,'Data (Per Faktur)'!$E:$E,'REKAP (Faktur)'!$Q45,'Data (Per Faktur)'!$K:$K,'REKAP (Faktur)'!$P$34) -> 0 | V45: =COUNTIFS('Data (Per Faktur)'!$A:$A,'REKAP (Faktur)'!V$36,'Data (Per Faktur)'!$E:$E,'REKAP (Faktur)'!$Q45,'Data (Per Faktur)'!$K:$K,'REKAP (Faktur)'!$P$34) -> 0 | W45: =COUNTIFS('Data (Per Faktur)'!$A:$A,'REKAP (Faktur)'!W$36,'Data (Per Faktur)'!$E:$E,'REKAP (Faktur)'!$Q45,'Data (Per Faktur)'!$K:$K,'REKAP (Faktur)'!$P$34) -> 0 | X45: =COUNTIFS('Data (Per Faktur)'!$A:$A,'REKAP (Faktur)'!X$36,'Data (Per Faktur)'!$E:$E,'REKAP (Faktur)'!$Q45,'Data (Per Faktur)'!$K:$K,'REKAP (Faktur)'!$P$34) -> 0 | Y45: =COUNTIFS('Data (Per Faktur)'!$A:$A,'REKAP (Faktur)'!Y$36,'Data (Per Faktur)'!$E:$E,'REKAP (Faktur)'!$Q45,'Data (Per Faktur)'!$K:$K,'REKAP (Faktur)'!$P$34) -> 0 | ... AC45: =COUNTIFS('Data (Per Faktur)'!$A:$A,'REKAP (Faktur)'!AC$36,'Data (Per Faktur)'!$E:$E,'REKAP (Faktur)'!$Q45,'Data (Per Faktur)'!$K:$K,'REKAP (Faktur)'!$P$34) -> 0 | AD45: =SUM(R45:AC45) -> 0 | AE45: =AD45/$AD$47 -> #DIV/0!
B46: Zakia | O46: =SUM(C46:N46) -> 0 | Q46: Zakia | R46: =COUNTIFS('Data (Per Faktur)'!$A:$A,'REKAP (Faktur)'!R$36,'Data (Per Faktur)'!$E:$E,'REKAP (Faktur)'!$Q46,'Data (Per Faktur)'!$K:$K,'REKAP (Faktur)'!$P$34) -> 0 | S46: =COUNTIFS('Data (Per Faktur)'!$A:$A,'REKAP (Faktur)'!S$36,'Data (Per Faktur)'!$E:$E,'REKAP (Faktur)'!$Q46,'Data (Per Faktur)'!$K:$K,'REKAP (Faktur)'!$P$34) -> 0 | T46: =COUNTIFS('Data (Per Faktur)'!$A:$A,'REKAP (Faktur)'!T$36,'Data (Per Faktur)'!$E:$E,'REKAP (Faktur)'!$Q46,'Data (Per Faktur)'!$K:$K,'REKAP (Faktur)'!$P$34) -> 0 | U46: =COUNTIFS('Data (Per Faktur)'!$A:$A,'REKAP (Faktur)'!U$36,'Data (Per Faktur)'!$E:$E,'REKAP (Faktur)'!$Q46,'Data (Per Faktur)'!$K:$K,'REKAP (Faktur)'!$P$34) -> 0 | V46: =COUNTIFS('Data (Per Faktur)'!$A:$A,'REKAP (Faktur)'!V$36,'Data (Per Faktur)'!$E:$E,'REKAP (Faktur)'!$Q46,'Data (Per Faktur)'!$K:$K,'REKAP (Faktur)'!$P$34) -> 0 | W46: =COUNTIFS('Data (Per Faktur)'!$A:$A,'REKAP (Faktur)'!W$36,'Data (Per Faktur)'!$E:$E,'REKAP (Faktur)'!$Q46,'Data (Per Faktur)'!$K:$K,'REKAP (Faktur)'!$P$34) -> 0 | X46: =COUNTIFS('Data (Per Faktur)'!$A:$A,'REKAP (Faktur)'!X$36,'Data (Per Faktur)'!$E:$E,'REKAP (Faktur)'!$Q46,'Data (Per Faktur)'!$K:$K,'REKAP (Faktur)'!$P$34) -> 0 | Y46: =COUNTIFS('Data (Per Faktur)'!$A:$A,'REKAP (Faktur)'!Y$36,'Data (Per Faktur)'!$E:$E,'REKAP (Faktur)'!$Q46,'Data (Per Faktur)'!$K:$K,'REKAP (Faktur)'!$P$34) -> 0 | ... AC46: =COUNTIFS('Data (Per Faktur)'!$A:$A,'REKAP (Faktur)'!AC$36,'Data (Per Faktur)'!$E:$E,'REKAP (Faktur)'!$Q46,'Data (Per Faktur)'!$K:$K,'REKAP (Faktur)'!$P$34) -> 0 | AD46: =SUM(R46:AC46) -> 0 | AE46: =AD46/$AD$47 -> #DIV/0!
B47: TOTAL | C47: =SUM(C37:C46) -> 0 | D47: =SUM(D37:D46) -> 0 | E47: =SUM(E37:E46) -> 0 | F47: =SUM(F37:F46) -> 0 | G47: =SUM(G37:G46) -> 0 | H47: =SUM(H37:H46) -> 0 | I47: =SUM(I37:I46) -> 0 | J47: =SUM(J37:J46) -> 0 | ... O47: =SUM(O37:O46) -> 0 | Q47: TOTAL | R47: =SUM(R37:R46) -> 0 | S47: =SUM(S37:S46) -> 0 | T47: =SUM(T37:T46) -> 0 | U47: =SUM(U37:U46) -> 0 | V47: =SUM(V37:V46) -> 0 | W47: =SUM(W37:W46) -> 0 | X47: =SUM(X37:X46) -> 0 | Y47: =SUM(Y37:Y46) -> 0 | ... AE47: =SUM(AE37:AE46) -> #DIV/0!
B49: JUMLAH SO (Per Faktur) | Q49: JUMLAH SO (Per Faktur)
B50: SC | C50: Jan | D50: Feb | E50: Mar | F50: Apr | G50: Mei | H50: Jun | I50: Jul | J50: Agst | K50: Sept | L50: Okt | M50: Nov | N50: Des | O50: Total | Q50: SC | R50: Jan | S50: Feb | T50: Mar | U50: Apr | V50: Mei | W50: Jun | X50: Jul | Y50: Agst | Z50: Sept | AA50: Okt | AB50: Nov | AC50: Des | AD50: Total
B51: Arasyi | O51: =SUM(C51:N51) -> 0 | Q51: Arasyi | AD51: =SUM(R51:AC51) -> 0
B52: Evi | O52: =SUM(C52:N52) -> 0 | Q52: Evi | AD52: =SUM(R52:AC52) -> 0
B53: Faisal | O53: =SUM(C53:N53) -> 0 | Q53: Faisal | AD53: =SUM(R53:AC53) -> 0
B54: Faris | O54: =SUM(C54:N54) -> 0 | Q54: Faris | AD54: =SUM(R54:AC54) -> 0
B55: Hendra | O55: =SUM(C55:N55) -> 0 | Q55: Hendra | AD55: =SUM(R55:AC55) -> 0
...

Sheet Data (Per Faktur)
A1: Bulan | B1: Tanggal Revisi | C1: Tanggal Faktur | D1: No. Faktur | E1: SC | F1: Admin SC | G1: Cust | H1: Keterangan | I1: Total | J1: Alasan | K1: Klasifikasi
A2: Januari | B2: 46027 | C2: 46007 | D2: B25016568 | E2: Nanda | F2: Sheila | G2: Nurhanifah | H2: Batal | I2: 2225000 | J2: Kios tidak transfer. | K2: Kios Batal TRF/ Tidak Tepat Janji
A3: Januari | B3: 46027 | C3: 46007 | D3: B25016590 | E3: Nanda | F3: Sheila | G3: Nurhanifah | H3: Batal | I3: 1407500 | J3: Kios tidak transfer. | K3: Kios Batal TRF/ Tidak Tepat Janji
A4: Januari | B4: 46028 | C4: 46013 | D4: A25002336 | E4: Nanda | F4: Sheila | G4: Online Shop Shopee | H4: Batal | I4: 944120 | J4: Retur, Alasan pembeli yg dikirim salah, padahal barang sudah sesuai pesanan | K4: Retur
A5: Januari | B5: 46028 | C5: 46025 | D5: D26000208 | E5: Nina | F5: Faris | G5: Akbar Tani, UD | H5: Karissnail 6 PL 20 X 500 gr (M2U)* (edit qty jadi 5 box 17 pack) | I5: 10419000 | J5: Retur, barang bocor | K5: Retur
A6: Januari | B6: 46030 | C6: 46030 | D6: D26000505 | E6: Nina | F6: Zakia | G6: Tenggulun Tani | H6: Antracol 70 WP 20 X 500 gr (edit harga 79.000) | I6: 33387500 | J6: SC salah harga (harga awal 78.000) | K6: Salah harga Oleh SC
A7: Januari | B7: 46031 | C7: 46024 | D7: A26000002 | E7: Nanda | F7: Sheila | G7: Online Shop Shopee | H7: Batal | I7: 57147 | J7: Shopee tidak dapat memproses krna alamat kirim terdampak banjir, info gudang belum kirim | K7: Lain - Lain (Acc oleh Direktur, Hpp berubah)
A8: Januari | B8: 46032 | C8: 46031 | D8: D26000595 | E8: Nina | F8: Reni | G8: Tani Sejati/Meggie | H8: Curacron 500 EC 40 X 250 ml (edit qty jadi 50box) | I8: 133000000 | J8: Kios merevisi qty order, karena expired pendek. | K8: Permintaan Cust (Ganti Kemasan, Ganti Identitas Pajak, Habis Musim, Ganti Qty)
A9: Januari | B9: 46034 | C9: 46029 | D9: A26000059 | E9: Nanda | F9: Sheila | G9: Online Shop Tik tok | H9: Batal | I9: 85250 | J9: Retur, Pembeli membatalkan pesanan sebelum barang dikirim oleh ekspedisi. | K9: Retur
A10: Januari | B10: 46034 | C10: 46028 | D10: B26000321 | E10: Nanda | F10: Faris | G10: Ahmad Mahsun Fuadi | H10: Batal | I10: 425000 | J10: Kios batal order karena barang belum dikirim, sedangkan hari ini rencana dibawa ke luar pulau. | K10: Pembatalan Order Oleh Kios
A11: Januari | B11: 46035 | C11: 46034 | D11: A26000086 | E11: Nanda | F11: Sheila | G11: Online Shop Shopee | H11: Batal | I11: 158020 | J11: Pembatalan otomatis dari shopee karena customer tidak melakukan pembayaran non COD. | K11: Pembatalan Order Oleh Kios
A12: Januari | B12: 46039 | C12: 46024 | D12: A26000028 | E12: Nanda | F12: Sheila | G12: Online Shop Tik tok | H12: Batal | I12: 70250 | J12: Retur, Pembeli membatalkan pesanan sebelum barang dikirim oleh ekspedisi. | K12: Retur
A13: Januari | B13: 46044 | C13: 46044 | D13: D26001232 | E13: Nina | F13: Ariyani | G13: Tani Maju/Aris | H13: edit transaksi (ganti ke cust Bumi Asih, UD/Hasan, Manohara 10Box bonus 1 Box harga 17.500) | I13: 3500000 | J13: kios awal merevisi orderan. | K13: Permintaan Cust (Ganti Kemasan, Ganti Identitas Pajak, Habis Musim, Ganti Qty)
... A76: Mei | B76: 46168 | C76: 46165 | D76: D26008009 | E76: Nina | F76: Ariyani | G76: Hariyono Sby | H76: Batal | I76: 13200000 | J76: Kios Batal Order karena saat barang sampai disana cust bilang klo stok dia masih ada dan exp 11/26, Barang langsung dikirim ke Damai Samsuri | K76: Pembatalan Order Oleh Kios

Sheet REKAP (Per Barang)
B2: REVISI FAKTUR BERDASARKAN ALASANNYA
B3: Periode Januari - Desember 2026
B4: Klasifikasi | C4: Januari | D4: Februari | E4: Maret | F4: April | G4: Mei | H4: Juni | I4: Juli | J4: Agustus | K4: September | L4: Oktober | M4: November | N4: Desember | O4: Total
B5: Permintaan Cust (Ganti Kemasan, Ganti Identitas Pajak, Habis Musim, Ganti Qty) | C5: =COUNTIFS('DATA (Per Barang)'!$A:$A,'REKAP (Per Barang)'!C$4,'DATA (Per Barang)'!$K:$K,'REKAP (Per Barang)'!$B5) -> 2 | D5: =COUNTIFS('DATA (Per Barang)'!$A:$A,'REKAP (Per Barang)'!D$4,'DATA (Per Barang)'!$K:$K,'REKAP (Per Barang)'!$B5) -> 5 | E5: =COUNTIFS('DATA (Per Barang)'!$A:$A,'REKAP (Per Barang)'!E$4,'DATA (Per Barang)'!$K:$K,'REKAP (Per Barang)'!$B5) -> 3 | F5: =COUNTIFS('DATA (Per Barang)'!$A:$A,'REKAP (Per Barang)'!F$4,'DATA (Per Barang)'!$K:$K,'REKAP (Per Barang)'!$B5) -> 5 | G5: =COUNTIFS('DATA (Per Barang)'!$A:$A,'REKAP (Per Barang)'!G$4,'DATA (Per Barang)'!$K:$K,'REKAP (Per Barang)'!$B5) -> 4 | H5: =COUNTIFS('DATA (Per Barang)'!$A:$A,'REKAP (Per Barang)'!H$4,'DATA (Per Barang)'!$K:$K,'REKAP (Per Barang)'!$B5) -> 0 | I5: =COUNTIFS('DATA (Per Barang)'!$A:$A,'REKAP (Per Barang)'!I$4,'DATA (Per Barang)'!$K:$K,'REKAP (Per Barang)'!$B5) -> 0 | J5: =COUNTIFS('DATA (Per Barang)'!$A:$A,'REKAP (Per Barang)'!J$4,'DATA (Per Barang)'!$K:$K,'REKAP (Per Barang)'!$B5) -> 0 | ... N5: =COUNTIFS('DATA (Per Barang)'!$A:$A,'REKAP (Per Barang)'!N$4,'DATA (Per Barang)'!$K:$K,'REKAP (Per Barang)'!$B5) -> 0 | O5: =SUM(C5:N5) -> 19
B6: Lain - Lain (Acc oleh Direktur, Hpp berubah) | C6: =COUNTIFS('DATA (Per Barang)'!$A:$A,'REKAP (Per Barang)'!C$4,'DATA (Per Barang)'!$K:$K,'REKAP (Per Barang)'!$B6) -> 1 | D6: =COUNTIFS('DATA (Per Barang)'!$A:$A,'REKAP (Per Barang)'!D$4,'DATA (Per Barang)'!$K:$K,'REKAP (Per Barang)'!$B6) -> 0 | E6: =COUNTIFS('DATA (Per Barang)'!$A:$A,'REKAP (Per Barang)'!E$4,'DATA (Per Barang)'!$K:$K,'REKAP (Per Barang)'!$B6) -> 0 | F6: =COUNTIFS('DATA (Per Barang)'!$A:$A,'REKAP (Per Barang)'!F$4,'DATA (Per Barang)'!$K:$K,'REKAP (Per Barang)'!$B6) -> 0 | G6: =COUNTIFS('DATA (Per Barang)'!$A:$A,'REKAP (Per Barang)'!G$4,'DATA (Per Barang)'!$K:$K,'REKAP (Per Barang)'!$B6) -> 0 | H6: =COUNTIFS('DATA (Per Barang)'!$A:$A,'REKAP (Per Barang)'!H$4,'DATA (Per Barang)'!$K:$K,'REKAP (Per Barang)'!$B6) -> 0 | I6: =COUNTIFS('DATA (Per Barang)'!$A:$A,'REKAP (Per Barang)'!I$4,'DATA (Per Barang)'!$K:$K,'REKAP (Per Barang)'!$B6) -> 0 | J6: =COUNTIFS('DATA (Per Barang)'!$A:$A,'REKAP (Per Barang)'!J$4,'DATA (Per Barang)'!$K:$K,'REKAP (Per Barang)'!$B6) -> 0 | ... N6: =COUNTIFS('DATA (Per Barang)'!$A:$A,'REKAP (Per Barang)'!N$4,'DATA (Per Barang)'!$K:$K,'REKAP (Per Barang)'!$B6) -> 0 | O6: =SUM(C6:N6) -> 1
B7: Pembatalan Order Oleh Kios | C7: =COUNTIFS('DATA (Per Barang)'!$A:$A,'REKAP (Per Barang)'!C$4,'DATA (Per Barang)'!$K:$K,'REKAP (Per Barang)'!$B7) -> 2 | D7: =COUNTIFS('DATA (Per Barang)'!$A:$A,'REKAP (Per Barang)'!D$4,'DATA (Per Barang)'!$K:$K,'REKAP (Per Barang)'!$B7) -> 3 | E7: =COUNTIFS('DATA (Per Barang)'!$A:$A,'REKAP (Per Barang)'!E$4,'DATA (Per Barang)'!$K:$K,'REKAP (Per Barang)'!$B7) -> 0 | F7: =COUNTIFS('Data (Per Faktur)'!$A:$A,'REKAP (Faktur)'!F$4,'Data (Per Faktur)'!$K:$K,'REKAP (Faktur)'!$B7) -> 2 | G7: =COUNTIFS('DATA (Per Barang)'!$A:$A,'REKAP (Per Barang)'!G$4,'DATA (Per Barang)'!$K:$K,'REKAP (Per Barang)'!$B7) -> 3 | H7: =COUNTIFS('Data (Per Faktur)'!$A:$A,'REKAP (Faktur)'!H$4,'Data (Per Faktur)'!$K:$K,'REKAP (Faktur)'!$B7) -> 0 | I7: =COUNTIFS('Data (Per Faktur)'!$A:$A,'REKAP (Faktur)'!I$4,'Data (Per Faktur)'!$K:$K,'REKAP (Faktur)'!$B7) -> 0 | J7: =COUNTIFS('Data (Per Faktur)'!$A:$A,'REKAP (Faktur)'!J$4,'Data (Per Faktur)'!$K:$K,'REKAP (Faktur)'!$B7) -> 0 | K7: =COUNTIFS('Data (Per Faktur)'!$A:$A,'REKAP (Faktur)'!K$4,'Data (Per Faktur)'!$K:$K,'REKAP (Faktur)'!$B7) -> 0 | L7: =COUNTIFS('Data (Per Faktur)'!$A:$A,'REKAP (Faktur)'!L$4,'Data (Per Faktur)'!$K:$K,'REKAP (Faktur)'!$B7) -> 0 | M7: =COUNTIFS('Data (Per Faktur)'!$A:$A,'REKAP (Faktur)'!M$4,'Data (Per Faktur)'!$K:$K,'REKAP (Faktur)'!$B7) -> 0 | N7: =COUNTIFS('DATA (Per Barang)'!$A:$A,'REKAP (Per Barang)'!N$4,'DATA (Per Barang)'!$K:$K,'REKAP (Per Barang)'!$B7) -> 0 | O7: =SUM(C7:N7) -> 10
B8: Retur | C8: =COUNTIFS('DATA (Per Barang)'!$A:$A,'REKAP (Per Barang)'!C$4,'DATA (Per Barang)'!$K:$K,'REKAP (Per Barang)'!$B8) -> 6 | D8: =COUNTIFS('DATA (Per Barang)'!$A:$A,'REKAP (Per Barang)'!D$4,'DATA (Per Barang)'!$K:$K,'REKAP (Per Barang)'!$B8) -> 4 | E8: =COUNTIFS('DATA (Per Barang)'!$A:$A,'REKAP (Per Barang)'!E$4,'DATA (Per Barang)'!$K:$K,'REKAP (Per Barang)'!$B8) -> 3 | F8: =COUNTIFS('Data (Per Faktur)'!$A:$A,'REKAP (Faktur)'!F$4,'Data (Per Faktur)'!$K:$K,'REKAP (Faktur)'!$B8) -> 5 | G8: =COUNTIFS('DATA (Per Barang)'!$A:$A,'REKAP (Per Barang)'!G$4,'DATA (Per Barang)'!$K:$K,'REKAP (Per Barang)'!$B8) -> 7 | H8: =COUNTIFS('Data (Per Faktur)'!$A:$A,'REKAP (Faktur)'!H$4,'Data (Per Faktur)'!$K:$K,'REKAP (Faktur)'!$B8) -> 0 | I8: =COUNTIFS('Data (Per Faktur)'!$A:$A,'REKAP (Faktur)'!I$4,'Data (Per Faktur)'!$K:$K,'REKAP (Faktur)'!$B8) -> 0 | J8: =COUNTIFS('Data (Per Faktur)'!$A:$A,'REKAP (Faktur)'!J$4,'Data (Per Faktur)'!$K:$K,'REKAP (Faktur)'!$B8) -> 0 | K8: =COUNTIFS('Data (Per Faktur)'!$A:$A,'REKAP (Faktur)'!K$4,'Data (Per Faktur)'!$K:$K,'REKAP (Faktur)'!$B8) -> 0 | L8: =COUNTIFS('Data (Per Faktur)'!$A:$A,'REKAP (Faktur)'!L$4,'Data (Per Faktur)'!$K:$K,'REKAP (Faktur)'!$B8) -> 0 | M8: =COUNTIFS('Data (Per Faktur)'!$A:$A,'REKAP (Faktur)'!M$4,'Data (Per Faktur)'!$K:$K,'REKAP (Faktur)'!$B8) -> 0 | N8: =COUNTIFS('DATA (Per Barang)'!$A:$A,'REKAP (Per Barang)'!N$4,'DATA (Per Barang)'!$K:$K,'REKAP (Per Barang)'!$B8) -> 0 | O8: =SUM(C8:N8) -> 25
